Workbook
Name _msoanchor_1: 'Input Data + Q2'!$X$29
Name _msoanchor_1: #REF!
Name _msoanchor_2: 'Input Data + Q2'!$D$39
Name _msoanchor_2: #REF!

Sheet Q1a
A1: Do not modify anything in this sheet except for the answer area | F1: Space available | M1: Quarter | N1: Q1’26 | O1: Q2’26 | P1: Q3’26 | Q1: Q4’26 | R1: Q1’27 | S1: Q2’27 | T1: Q3’27 | U1: Q4’27
F2: Fab 1 | G2: Fab 2 | H2: Fab 3 | K2: Total costs over 8 quarters | M2: Node 1 | N2: 12000 | O2: 10000 | P2: 8500 | Q2: 7500 | R2: 6000 | S2: 5000 | T2: 4000 | U2: 2000 | AP2: All capacity ok?
F3: 1500 | G3: 1300 | H3: 700 | J3: minimize this -> | K3: =F23+F35+F47+F59+F71+F83+F95+F25+F37+F49+F61+F73+F85+F97+Y6 -> 587000000 | M3: Node 2 | N3: 5000 | O3: 5200 | P3: 5400 | Q3: 5600 | R3: 6000 | S3: 6500 | T3: 7000 | U3: 7500 | AP3: =AND(AU8:BB25) -> TRUE | AQ3: <- make sure its green
A4: All constraints fulfilled? | B4: =AND(K7,V8,AP3) -> FALSE | C4: <- make sure its green | M4: Node 3 | N4: 3000 | O4: 4500 | P4: 7000 | Q4: 8000 | R4: 9000 | S4: 11000 | T4: 13000 | U4: 16000
O5: =ROUNDUP(45*O2/10080/0.84,0) -> 54 | P5: =ROUNDUP(45*P2/10080/0.84,0) -> 46 | Q5: =ROUNDUP(45*Q2/10080/0.84,0) -> 40 | R5: =ROUNDUP(45*R2/10080/0.84,0) -> 32 | S5: =ROUNDUP(45*S2/10080/0.84,0) -> 27 | T5: =ROUNDUP(45*T2/10080/0.84,0) -> 22 | AU5: Enough mintech + TOR tools to run the assigned loading?
C6: Tooling plan (to fill) | F6: Solution Validation | K6: All space within limit? | O6: Node Wafer Stepflow Distribution for each fab for each quarter | T6: Solution Validation | V6: All loading fulfilled? | X6: Total transfer costs: | Y6: =SUM(_xlfn.ANCHORARRAY(Y8)) -> 0 | AB6: mintech | AC6: TOR | AD6: mintech | AE6: TOR | AF6: mintech | AG6: TOR | AH6: mintech | AI6: TOR | AJ6: mintech | AK6: mintech | AL6: TOR | AM6: mintech | AN6: mintech | AO6: TOR | AP6: Enough mintech + TOR tools to run the assigned loading?
B7: WS Name | C7: Fab 1 - WS Count | D7: Fab 2 - WS Count | E7: Fab 3 - WS Count | F7: Fab 1 space | G7: Fab 2 space | H7: Fab 3 space | K7: {=AND(F8:H8<$F$3:$H$3,F20:H20<$F$3:$H$3,F32:H32<$F$3:$H$3,F44:H44<$F$3:$H$3,F56:H56<$F$3:$H$3,F68:H68<$F$3:$H$3,F80:H80<$F$3:$H$3,F92:H92<$F$3:$H$3)} -> TRUE | O7: Quarter | P7: Node | Q7: Step | R7: Fab | S7: Loading (to fill) | T7: Loading fulfilled? | X7: Cross-fab transfer count | Y7: Transfer costs | AA7: Mintech preference rank | AB7: WS (mintech) | AC7: WS (TOR) | AD7: RPT (mintech) | AE7: RPT (TOR) | AF7: Util (mintech) | AG7: Util (TOR) | AH7: Tool requirement if running on mintech | AI7: Tool requirement if running on TOR | AJ7: Cumulative mintech req | AK7: Available mintech tools | AL7: Available TOR tools | AM7: Overflow cumreq | AN7: Req on mintech | AO7: Req on TOR | AR7: Fab | AU7: Q1’26 | AV7: Q2’26 | AW7: Q3’26 | AX7: Q4’26 | AY7: Q1’27 | AZ7: Q2’27 | BA7: Q3’27 | BB7: Q4’27
A8: WS Component for Q1’26 | B8: A | C8: 50 | D8: 35 | E8: 0 | F8: {=SUM(C8:C19*data!$B$3:$B$14)} -> 1235.7 | G8: {=SUM(D8:D19*data!$B$3:$B$14)} -> 996.9 | H8: {=SUM(E8:E19*data!$B$3:$B$14)} -> 636.03 | I8: <- make sure its green | O8: Q1’26 | P8: 1 | Q8: 1 | R8: 1 | T8: =(S8+S9+S10)=N2 -> FALSE | V8: =AND(T8:T1039) -> FALSE | W8: <- make sure its green | X8: 0 | Y8: {=X8:X1039*50*13} -> 0 | AA8: 4 | AB8: D | AC8: D+ | AD8: 14 | AE8: 12 | AF8: 0.8 | AG8: 0.88 | AH8: {=$S8:$S1039*AD8:AD1039/10080/AF8:AF1039} -> 0 | AI8: {=$S8:$S1039*AE8:AE1039/10080/AG8:AG1039} -> 0 | AJ8: =SUMIFS(AH$8:AH$1039,$O$8:$O$1039,O8,$AB$8:$AB$1039,AB8,$R$8:$R$1039,R8,$AA$8:$AA$1039,"<="&AA8) -> 0 | AK8: =C11 -> 50 | AL8: =C17 -> 0 | AM8: =MAX(0,AJ8-AK8) -> 0 | AN8: =IF(AM8=0,AH8,IF(AM8>=AH8,0,AH8-AM8)) -> 0 | AO8: =IF(AM8>=AH8,AI8,AI8*AM8/AH8) -> 0 | AP8: {=INDEX($AU$8:$BB$25,6*(R8-1)+MATCH(AB8,$AS$8:$AS$13,0),MATCH(O8,$AU$7:$BB$7,0))} -> TRUE | AR8: 1 | AS8: A | AT8: A+ | AU8: =AND(SUMIFS($AN$8:$AN$1039,$O$8:$O$1039,AU7,$AB$8:$AB$1039,AS8,$R$8:$R$1039,AR8)<=C8,SUMIFS($AO$8:$AO$1039,$O$8:$O$1039,AU7,$AB$8:$AB$1039,AS8,$R$8:$R$1039,AR8)<=C14) -> TRUE | AV8: =AND(SUMIFS($AN$8:$AN$1039,$O$8:$O$1039,AV7,$AB$8:$AB$1039,AS8,$R$8:$R$1039,AR8)<=C20,SUMIFS($AO$8:$AO$1039,$O$8:$O$1039,AV7,$AB$8:$AB$1039,AS8,$R$8:$R$1039,AR8)<=C26) -> TRUE | AW8: =AND(SUMIFS($AN$8:$AN$1039,$O$8:$O$1039,AW7,$AB$8:$AB$1039,AS8,$R$8:$R$1039,AR8)<=C32,SUMIFS($AO$8:$AO$1039,$O$8:$O$1039,AW7,$AB$8:$AB$1039,AS8,$R$8:$R$1039,AR8)<=C38) -> TRUE | AX8: =AND(SUMIFS($AN$8:$AN$1039,$O$8:$O$1039,AX7,$AB$8:$AB$1039,AS8,$R$8:$R$1039,AR8)<=C44,SUMIFS($AO$8:$AO$1039,$O$8:$O$1039,AX7,$AB$8:$AB$1039,AS8,$R$8:$R$1039,AR8)<=C50) -> TRUE | AY8: =AND(SUMIFS($AN$8:$AN$1039,$O$8:$O$1039,AY7,$AB$8:$AB$1039,AS8,$R$8:$R$1039,AR8)<=C56,SUMIFS($AO$8:$AO$1039,$O$8:$O$1039,AY7,$AB$8:$AB$1039,AS8,$R$8:$R$1039,AR8)<=C62) -> TRUE | AZ8: =AND(SUMIFS($AN$8:$AN$1039,$O$8:$O$1039,AZ7,$AB$8:$AB$1039,AS8,$R$8:$R$1039,AR8)<=C68,SUMIFS($AO$8:$AO$1039,$O$8:$O$1039,AZ7,$AB$8:$AB$1039,AS8,$R$8:$R$1039,AR8)<=C74) -> TRUE | BA8: =AND(SUMIFS($AN$8:$AN$1039,$O$8:$O$1039,BA7,$AB$8:$AB$1039,AS8,$R$8:$R$1039,AR8)<=C80,SUMIFS($AO$8:$AO$1039,$O$8:$O$1039,BA7,$AB$8:$AB$1039,AS8,$R$8:$R$1039,AR8)<=C86) -> TRUE | BB8: =AND(SUMIFS($AN$8:$AN$1039,$O$8:$O$1039,BB7,$AB$8:$AB$1039,AS8,$R$8:$R$1039,AR8)<=C92,SUMIFS($AO$8:$AO$1039,$O$8:$O$1039,BB7,$AB$8:$AB$1039,AS8,$R$8:$R$1039,AR8)<=C98) -> TRUE
B9: B | C9: 25 | D9: 30 | E9: 0 | O9: Q1’26 | P9: 1 | Q9: 1 | R9: 2 | T9: =(S8+S9+S10)=N2 -> FALSE | X9: 0 | Y9: 0 | AA9: 4 | AB9: D | AC9: D+ | AD9: 14 | AE9: 12 | AF9: 0.8 | AG9: 0.88 | AH9: 0 | AI9: 0 | AJ9: =SUMIFS(AH$8:AH$1039,$O$8:$O$1039,O9,$AB$8:$AB$1039,AB9,$R$8:$R$1039,R9,$AA$8:$AA$1039,"<="&AA9) -> 0 | AK9: =D11 -> 50 | AL9: =D17 -> 0 | AM9: =MAX(0,AJ9-AK9) -> 0 | AN9: =IF(AM9=0,AH9,IF(AM9>=AH9,0,AH9-AM9)) -> 0 | AO9: =IF(AM9>=AH9,AI9,AI9*AM9/AH9) -> 0 | AP9: {=INDEX($AU$8:$BB$25,6*(R9-1)+MATCH(AB9,$AS$8:$AS$13,0),MATCH(O9,$AU$7:$BB$7,0))} -> TRUE | AR9: 1 | AS9: B | AT9: B+ | AU9: =AND(SUMIFS($AN$8:$AN$1039,$O$8:$O$1039,AU7,$AB$8:$AB$1039,AS9,$R$8:$R$1039,AR9)<=C9,SUMIFS($AO$8:$AO$1039,$O$8:$O$1039,AU7,$AB$8:$AB$1039,AS9,$R$8:$R$1039,AR9)<=C15) -> TRUE | AV9: =AND(SUMIFS($AN$8:$AN$1039,$O$8:$O$1039,AV7,$AB$8:$AB$1039,AS9,$R$8:$R$1039,AR9)<=C21,SUMIFS($AO$8:$AO$1039,$O$8:$O$1039,AV7,$AB$8:$AB$1039,AS9,$R$8:$R$1039,AR9)<=C27) -> TRUE | AW9: =AND(SUMIFS($AN$8:$AN$1039,$O$8:$O$1039,AW7,$AB$8:$AB$1039,AS9,$R$8:$R$1039,AR9)<=C33,SUMIFS($AO$8:$AO$1039,$O$8:$O$1039,AW7,$AB$8:$AB$1039,AS9,$R$8:$R$1039,AR9)<=C39) -> TRUE | AX9: =AND(SUMIFS($AN$8:$AN$1039,$O$8:$O$1039,AX7,$AB$8:$AB$1039,AS9,$R$8:$R$1039,AR9)<=C45,SUMIFS($AO$8:$AO$1039,$O$8:$O$1039,AX7,$AB$8:$AB$1039,AS9,$R$8:$R$1039,AR9)<=C51) -> TRUE | AY9: =AND(SUMIFS($AN$8:$AN$1039,$O$8:$O$1039,AY7,$AB$8:$AB$1039,AS9,$R$8:$R$1039,AR9)<=C57,SUMIFS($AO$8:$AO$1039,$O$8:$O$1039,AY7,$AB$8:$AB$1039,AS9,$R$8:$R$1039,AR9)<=C63) -> TRUE | AZ9: =AND(SUMIFS($AN$8:$AN$1039,$O$8:$O$1039,AZ7,$AB$8:$AB$1039,AS9,$R$8:$R$1039,AR9)<=C69,SUMIFS($AO$8:$AO$1039,$O$8:$O$1039,AZ7,$AB$8:$AB$1039,AS9,$R$8:$R$1039,AR9)<=C75) -> TRUE | BA9: =AND(SUMIFS($AN$8:$AN$1039,$O$8:$O$1039,BA7,$AB$8:$AB$1039,AS9,$R$8:$R$1039,AR9)<=C81,SUMIFS($AO$8:$AO$1039,$O$8:$O$1039,BA7,$AB$8:$AB$1039,AS9,$R$8:$R$1039,AR9)<=C87) -> TRUE | BB9: =AND(SUMIFS($AN$8:$AN$1039,$O$8:$O$1039,BB7,$AB$8:$AB$1039,AS9,$R$8:$R$1039,AR9)<=C93,SUMIFS($AO$8:$AO$1039,$O$8:$O$1039,BB7,$AB$8:$AB$1039,AS9,$R$8:$R$1039,AR9)<=C99) -> TRUE
B10: C | C10: 0 | D10: 0 | E10: 40 | O10: Q1’26 | P10: 1 | Q10: 1 | R10: 3 | T10: =(S8+S9+S10)=N2 -> FALSE | X10: 0 | Y10: 0 | AA10: 4 | AB10: D | AC10: D+ | AD10: 14 | AE10: 12 | AF10: 0.8 | AG10: 0.88 | AH10: 0 | AI10: 0 | AJ10: =SUMIFS(AH$8:AH$1039,$O$8:$O$1039,O10,$AB$8:$AB$1039,AB10,$R$8:$R$1039,R10,$AA$8:$AA$1039,"<="&AA10) -> 0 | AK10: =E11 -> 35 | AL10: =E17 -> 0 | AM10: =MAX(0,AJ10-AK10) -> 0 | AN10: =IF(AM10=0,AH10,IF(AM10>=AH10,0,AH10-AM10)) -> 0 | AO10: =IF(AM10>=AH10,AI10,AI10*AM10/AH10) -> 0 | AP10: {=INDEX($AU$8:$BB$25,6*(R10-1)+MATCH(AB10,$AS$8:$AS$13,0),MATCH(O10,$AU$7:$BB$7,0))} -> TRUE | AR10: 1 | AS10: C | AT10: C+ | AU10: =AND(SUMIFS($AN$8:$AN$1039,$O$8:$O$1039,AU7,$AB$8:$AB$1039,AS10,$R$8:$R$1039,AR10)<=C10,SUMIFS($AO$8:$AO$1039,$O$8:$O$1039,AU7,$AB$8:$AB$1039,AS10,$R$8:$R$1039,AR10)<=C16) -> TRUE | AV10: =AND(SUMIFS($AN$8:$AN$1039,$O$8:$O$1039,AV7,$AB$8:$AB$1039,AS10,$R$8:$R$1039,AR10)<=C22,SUMIFS($AO$8:$AO$1039,$O$8:$O$1039,AV7,$AB$8:$AB$1039,AS10,$R$8:$R$1039,AR10)<=C28) -> TRUE | AW10: =AND(SUMIFS($AN$8:$AN$1039,$O$8:$O$1039,AW7,$AB$8:$AB$1039,AS10,$R$8:$R$1039,AR10)<=C34,SUMIFS($AO$8:$AO$1039,$O$8:$O$1039,AW7,$AB$8:$AB$1039,AS10,$R$8:$R$1039,AR10)<=C40) -> TRUE | AX10: =AND(SUMIFS($AN$8:$AN$1039,$O$8:$O$1039,AX7,$AB$8:$AB$1039,AS10,$R$8:$R$1039,AR10)<=C46,SUMIFS($AO$8:$AO$1039,$O$8:$O$1039,AX7,$AB$8:$AB$1039,AS10,$R$8:$R$1039,AR10)<=C52) -> TRUE | AY10: =AND(SUMIFS($AN$8:$AN$1039,$O$8:$O$1039,AY7,$AB$8:$AB$1039,AS10,$R$8:$R$1039,AR10)<=C58,SUMIFS($AO$8:$AO$1039,$O$8:$O$1039,AY7,$AB$8:$AB$1039,AS10,$R$8:$R$1039,AR10)<=C64) -> TRUE | AZ10: =AND(SUMIFS($AN$8:$AN$1039,$O$8:$O$1039,AZ7,$AB$8:$AB$1039,AS10,$R$8:$R$1039,AR10)<=C70,SUMIFS($AO$8:$AO$1039,$O$8:$O$1039,AZ7,$AB$8:$AB$1039,AS10,$R$8:$R$1039,AR10)<=C76) -> TRUE | BA10: =AND(SUMIFS($AN$8:$AN$1039,$O$8:$O$1039,BA7,$AB$8:$AB$1039,AS10,$R$8:$R$1039,AR10)<=C82,SUMIFS($AO$8:$AO$1039,$O$8:$O$1039,BA7,$AB$8:$AB$1039,AS10,$R$8:$R$1039,AR10)<=C88) -> TRUE | BB10: =AND(SUMIFS($AN$8:$AN$1039,$O$8:$O$1039,BB7,$AB$8:$AB$1039,AS10,$R$8:$R$1039,AR10)<=C94,SUMIFS($AO$8:$AO$1039,$O$8:$O$1039,BB7,$AB$8:$AB$1039,AS10,$R$8:$R$1039,AR10)<=C100) -> TRUE
B11: D | C11: 50 | D11: 50 | E11: 35 | O11: Q1’26 | P11: 1 | Q11: 2 | R11: 1 | T11: =(S11+S12+S13)=N2 -> FALSE | X11: =MAX(S8-S11,0) -> 0 | Y11: 0 | AA11: 10 | AB11: F | AC11: F+ | AD11: 25 | AE11: 21 | AF11: 0.8 | AG11: 0.9 | AH11: 0 | AI11: 0 | AJ11: =SUMIFS(AH$8:AH$1039,$O$8:$O$1039,O11,$AB$8:$AB$1039,AB11,$R$8:$R$1039,R11,$AA$8:$AA$1039,"<="&AA11) -> 0 | AK11: =C13 -> 90 | AL11: =C19 -> 0 | AM11: =MAX(0,AJ11-AK11) -> 0 | AN11: =IF(AM11=0,AH11,IF(AM11>=AH11,0,AH11-AM11)) -> 0 | AO11: =IF(AM11>=AH11,AI11,AI11*AM11/AH11) -> 0 | AP11: {=INDEX($AU$8:$BB$25,6*(R11-1)+MATCH(AB11,$AS$8:$AS$13,0),MATCH(O11,$AU$7:$BB$7,0))} -> TRUE | AR11: 1 | AS11: D | AT11: D+ | AU11: =AND(SUMIFS($AN$8:$AN$1039,$O$8:$O$1039,AU7,$AB$8:$AB$1039,AS11,$R$8:$R$1039,AR11)<=C11,SUMIFS($AO$8:$AO$1039,$O$8:$O$1039,AU7,$AB$8:$AB$1039,AS11,$R$8:$R$1039,AR11)<=C17) -> TRUE | AV11: =AND(SUMIFS($AN$8:$AN$1039,$O$8:$O$1039,AV7,$AB$8:$AB$1039,AS11,$R$8:$R$1039,AR11)<=C23,SUMIFS($AO$8:$AO$1039,$O$8:$O$1039,AV7,$AB$8:$AB$1039,AS11,$R$8:$R$1039,AR11)<=C29) -> TRUE | AW11: =AND(SUMIFS($AN$8:$AN$1039,$O$8:$O$1039,AW7,$AB$8:$AB$1039,AS11,$R$8:$R$1039,AR11)<=C35,SUMIFS($AO$8:$AO$1039,$O$8:$O$1039,AW7,$AB$8:$AB$1039,AS11,$R$8:$R$1039,AR11)<=C41) -> TRUE | AX11: =AND(SUMIFS($AN$8:$AN$1039,$O$8:$O$1039,AX7,$AB$8:$AB$1039,AS11,$R$8:$R$1039,AR11)<=C47,SUMIFS($AO$8:$AO$1039,$O$8:$O$1039,AX7,$AB$8:$AB$1039,AS11,$R$8:$R$1039,AR11)<=C53) -> TRUE | AY11: =AND(SUMIFS($AN$8:$AN$1039,$O$8:$O$1039,AY7,$AB$8:$AB$1039,AS11,$R$8:$R$1039,AR11)<=C59,SUMIFS($AO$8:$AO$1039,$O$8:$O$1039,AY7,$AB$8:$AB$1039,AS11,$R$8:$R$1039,AR11)<=C65) -> TRUE | AZ11: =AND(SUMIFS($AN$8:$AN$1039,$O$8:$O$1039,AZ7,$AB$8:$AB$1039,AS11,$R$8:$R$1039,AR11)<=C71,SUMIFS($AO$8:$AO$1039,$O$8:$O$1039,AZ7,$AB$8:$AB$1039,AS11,$R$8:$R$1039,AR11)<=C77) -> TRUE | BA11: =AND(SUMIFS($AN$8:$AN$1039,$O$8:$O$1039,BA7,$AB$8:$AB$1039,AS11,$R$8:$R$1039,AR11)<=C83,SUMIFS($AO$8:$AO$1039,$O$8:$O$1039,BA7,$AB$8:$AB$1039,AS11,$R$8:$R$1039,AR11)<=C89) -> TRUE | BB11: =AND(SUMIFS($AN$8:$AN$1039,$O$8:$O$1039,BB7,$AB$8:$AB$1039,AS11,$R$8:$R$1039,AR11)<=C95,SUMIFS($AO$8:$AO$1039,$O$8:$O$1039,BB7,$AB$8:$AB$1039,AS11,$R$8:$R$1039,AR11)<=C101) -> TRUE
B12: E | C12: 40 | D12: 30 | E12: 16 | O12: Q1’26 | P12: 1 | Q12: 2 | R12: 2 | T12: =(S11+S12+S13)=N2 -> FALSE | X12: =MAX(S9-S12,0) -> 0 | Y12: 0 | AA12: 10 | AB12: F | AC12: F+ | AD12: 25 | AE12: 21 | AF12: 0.8 | AG12: 0.9 | AH12: 0 | AI12: 0 | AJ12: =SUMIFS(AH$8:AH$1039,$O$8:$O$1039,O12,$AB$8:$AB$1039,AB12,$R$8:$R$1039,R12,$AA$8:$AA$1039,"<="&AA12) -> 0 | AK12: =D13 -> 60 | AL12: =D19 -> 0 | AM12: =MAX(0,AJ12-AK12) -> 0 | AN12: =IF(AM12=0,AH12,IF(AM12>=AH12,0,AH12-AM12)) -> 0 | AO12: =IF(AM12>=AH12,AI12,AI12*AM12/AH12) -> 0 | AP12: {=INDEX($AU$8:$BB$25,6*(R12-1)+MATCH(AB12,$AS$8:$AS$13,0),MATCH(O12,$AU$7:$BB$7,0))} -> TRUE | AR12: 1 | AS12: E | AT12: E+ | AU12: =AND(SUMIFS($AN$8:$AN$1039,$O$8:$O$1039,AU7,$AB$8:$AB$1039,AS12,$R$8:$R$1039,AR12)<=C12,SUMIFS($AO$8:$AO$1039,$O$8:$O$1039,AU7,$AB$8:$AB$1039,AS12,$R$8:$R$1039,AR12)<=C18) -> TRUE | AV12: =AND(SUMIFS($AN$8:$AN$1039,$O$8:$O$1039,AV7,$AB$8:$AB$1039,AS12,$R$8:$R$1039,AR12)<=C24,SUMIFS($AO$8:$AO$1039,$O$8:$O$1039,AV7,$AB$8:$AB$1039,AS12,$R$8:$R$1039,AR12)<=C30) -> TRUE | AW12: =AND(SUMIFS($AN$8:$AN$1039,$O$8:$O$1039,AW7,$AB$8:$AB$1039,AS12,$R$8:$R$1039,AR12)<=C36,SUMIFS($AO$8:$AO$1039,$O$8:$O$1039,AW7,$AB$8:$AB$1039,AS12,$R$8:$R$1039,AR12)<=C42) -> TRUE | AX12: =AND(SUMIFS($AN$8:$AN$1039,$O$8:$O$1039,AX7,$AB$8:$AB$1039,AS12,$R$8:$R$1039,AR12)<=C48,SUMIFS($AO$8:$AO$1039,$O$8:$O$1039,AX7,$AB$8:$AB$1039,AS12,$R$8:$R$1039,AR12)<=C54) -> TRUE | AY12: =AND(SUMIFS($AN$8:$AN$1039,$O$8:$O$1039,AY7,$AB$8:$AB$1039,AS12,$R$8:$R$1039,AR12)<=C60,SUMIFS($AO$8:$AO$1039,$O$8:$O$1039,AY7,$AB$8:$AB$1039,AS12,$R$8:$R$1039,AR12)<=C66) -> TRUE | AZ12: =AND(SUMIFS($AN$8:$AN$1039,$O$8:$O$1039,AZ7,$AB$8:$AB$1039,AS12,$R$8:$R$1039,AR12)<=C72,SUMIFS($AO$8:$AO$1039,$O$8:$O$1039,AZ7,$AB$8:$AB$1039,AS12,$R$8:$R$1039,AR12)<=C78) -> TRUE | BA12: =AND(SUMIFS($AN$8:$AN$1039,$O$8:$O$1039,BA7,$AB$8:$AB$1039,AS12,$R$8:$R$1039,AR12)<=C84,SUMIFS($AO$8:$AO$1039,$O$8:$O$1039,BA7,$AB$8:$AB$1039,AS12,$R$8:$R$1039,AR12)<=C90) -> TRUE | BB12: =AND(SUMIFS($AN$8:$AN$1039,$O$8:$O$1039,BB7,$AB$8:$AB$1039,AS12,$R$8:$R$1039,AR12)<=C96,SUMIFS($AO$8:$AO$1039,$O$8:$O$1039,BB7,$AB$8:$AB$1039,AS12,$R$8:$R$1039,AR12)<=C102) -> TRUE
B13: F | C13: 90 | D13: 60 | E13: 36 | O13: Q1’26 | P13: 1 | Q13: 2 | R13: 3 | T13: =(S11+S12+S13)=N2 -> FALSE | X13: =MAX(S10-S13,0) -> 0 | Y13: 0 | AA13: 10 | AB13: F | AC13: F+ | AD13: 25 | AE13: 21 | AF13: 0.8 | AG13: 0.9 | AH13: 0 | AI13: 0 | AJ13: =SUMIFS(AH$8:AH$1039,$O$8:$O$1039,O13,$AB$8:$AB$1039,AB13,$R$8:$R$1039,R13,$AA$8:$AA$1039,"<="&AA13) -> 0 | AK13: =E13 -> 36 | AL13: =E19 -> 0 | AM13: =MAX(0,AJ13-AK13) -> 0 | AN13: =IF(AM13=0,AH13,IF(AM13>=AH13,0,AH13-AM13)) -> 0 | AO13: =IF(AM13>=AH13,AI13,AI13*AM13/AH13) -> 0 | AP13: {=INDEX($AU$8:$BB$25,6*(R13-1)+MATCH(AB13,$AS$8:$AS$13,0),MATCH(O13,$AU$7:$BB$7,0))} -> TRUE | AR13: 1 | AS13: F | AT13: F+ | AU13: =AND(SUMIFS($AN$8:$AN$1039,$O$8:$O$1039,AU7,$AB$8:$AB$1039,AS13,$R$8:$R$1039,AR13)<=C13,SUMIFS($AO$8:$AO$1039,$O$8:$O$1039,AU7,$AB$8:$AB$1039,AS13,$R$8:$R$1039,AR13)<=C19) -> TRUE | AV13: =AND(SUMIFS($AN$8:$AN$1039,$O$8:$O$1039,AV7,$AB$8:$AB$1039,AS13,$R$8:$R$1039,AR13)<=C25,SUMIFS($AO$8:$AO$1039,$O$8:$O$1039,AV7,$AB$8:$AB$1039,AS13,$R$8:$R$1039,AR13)<=C31) -> TRUE | AW13: =AND(SUMIFS($AN$8:$AN$1039,$O$8:$O$1039,AW7,$AB$8:$AB$1039,AS13,$R$8:$R$1039,AR13)<=C37,SUMIFS($AO$8:$AO$1039,$O$8:$O$1039,AW7,$AB$8:$AB$1039,AS13,$R$8:$R$1039,AR13)<=C43) -> TRUE | AX13: =AND(SUMIFS($AN$8:$AN$1039,$O$8:$O$1039,AX7,$AB$8:$AB$1039,AS13,$R$8:$R$1039,AR13)<=C49,SUMIFS($AO$8:$AO$1039,$O$8:$O$1039,AX7,$AB$8:$AB$1039,AS13,$R$8:$R$1039,AR13)<=C55) -> TRUE | AY13: =AND(SUMIFS($AN$8:$AN$1039,$O$8:$O$1039,AY7,$AB$8:$AB$1039,AS13,$R$8:$R$1039,AR13)<=C61,SUMIFS($AO$8:$AO$1039,$O$8:$O$1039,AY7,$AB$8:$AB$1039,AS13,$R$8:$R$1039,AR13)<=C67) -> TRUE | AZ13: =AND(SUMIFS($AN$8:$AN$1039,$O$8:$O$1039,AZ7,$AB$8:$AB$1039,AS13,$R$8:$R$1039,AR13)<=C73,SUMIFS($AO$8:$AO$1039,$O$8:$O$1039,AZ7,$AB$8:$AB$1039,AS13,$R$8:$R$1039,AR13)<=C79) -> TRUE | BA13: =AND(SUMIFS($AN$8:$AN$1039,$O$8:$O$1039,BA7,$AB$8:$AB$1039,AS13,$R$8:$R$1039,AR13)<=C85,SUMIFS($AO$8:$AO$1039,$O$8:$O$1039,BA7,$AB$8:$AB$1039,AS13,$R$8:$R$1039,AR13)<=C91) -> TRUE | BB13: =AND(SUMIFS($AN$8:$AN$1039,$O$8:$O$1039,BB7,$AB$8:$AB$1039,AS13,$R$8:$R$1039,AR13)<=C97,SUMIFS($AO$8:$AO$1039,$O$8:$O$1039,BB7,$AB$8:$AB$1039,AS13,$R$8:$R$1039,AR13)<=C103) -> TRUE
B14: A+ | C14: 0 | D14: 0 | E14: 0 | O14: Q1’26 | P14: 1 | Q14: 3 | R14: 1 | T14: =(S14+S15+S16)=N2 -> FALSE | X14: =MAX(S11-S14,0) -> 0 | Y14: 0 | AA14: 8 | AB14: F | AC14: F+ | AD14: 27 | AE14: 23 | AF14: 0.8 | AG14: 0.9 | AH14: 0 | AI14: 0 | AJ14: =SUMIFS(AH$8:AH$1039,$O$8:$O$1039,O14,$AB$8:$AB$1039,AB14,$R$8:$R$1039,R14,$AA$8:$AA$1039,"<="&AA14) -> 0 | AK14: =C13 -> 90 | AL14: =C19 -> 0 | AM14: =MAX(0,AJ14-AK14) -> 0 | AN14: =IF(AM14=0,AH14,IF(AM14>=AH14,0,AH14-AM14)) -> 0 | AO14: =IF(AM14>=AH14,AI14,AI14*AM14/AH14) -> 0 | AP14: {=INDEX($AU$8:$BB$25,6*(R14-1)+MATCH(AB14,$AS$8:$AS$13,0),MATCH(O14,$AU$7:$BB$7,0))} -> TRUE | AR14: 2 | AS14: A | AT14: A+ | AU14: =AND(SUMIFS($AN$8:$AN$1039,$O$8:$O$1039,AU7,$AB$8:$AB$1039,AS14,$R$8:$R$1039,AR14)<=D8,SUMIFS($AO$8:$AO$1039,$O$8:$O$1039,AU7,$AB$8:$AB$1039,AS14,$R$8:$R$1039,AR14)<=D14) -> TRUE | AV14: =AND(SUMIFS($AN$8:$AN$1039,$O$8:$O$1039,AV7,$AB$8:$AB$1039,AS14,$R$8:$R$1039,AR14)<=D20,SUMIFS($AO$8:$AO$1039,$O$8:$O$1039,AV7,$AB$8:$AB$1039,AS14,$R$8:$R$1039,AR14)<=D26) -> TRUE | AW14: =AND(SUMIFS($AN$8:$AN$1039,$O$8:$O$1039,AW7,$AB$8:$AB$1039,AS14,$R$8:$R$1039,AR14)<=D32,SUMIFS($AO$8:$AO$1039,$O$8:$O$1039,AW7,$AB$8:$AB$1039,AS14,$R$8:$R$1039,AR14)<=D38) -> TRUE | AX14: =AND(SUMIFS($AN$8:$AN$1039,$O$8:$O$1039,AX7,$AB$8:$AB$1039,AS14,$R$8:$R$1039,AR14)<=D44,SUMIFS($AO$8:$AO$1039,$O$8:$O$1039,AX7,$AB$8:$AB$1039,AS14,$R$8:$R$1039,AR14)<=D50) -> TRUE | AY14: =AND(SUMIFS($AN$8:$AN$1039,$O$8:$O$1039,AY7,$AB$8:$AB$1039,AS14,$R$8:$R$1039,AR14)<=D56,SUMIFS($AO$8:$AO$1039,$O$8:$O$1039,AY7,$AB$8:$AB$1039,AS14,$R$8:$R$1039,AR14)<=D62) -> TRUE | AZ14: =AND(SUMIFS($AN$8:$AN$1039,$O$8:$O$1039,AZ7,$AB$8:$AB$1039,AS14,$R$8:$R$1039,AR14)<=D68,SUMIFS($AO$8:$AO$1039,$O$8:$O$1039,AZ7,$AB$8:$AB$1039,AS14,$R$8:$R$1039,AR14)<=D74) -> TRUE | BA14: =AND(SUMIFS($AN$8:$AN$1039,$O$8:$O$1039,BA7,$AB$8:$AB$1039,AS14,$R$8:$R$1039,AR14)<=D80,SUMIFS($AO$8:$AO$1039,$O$8:$O$1039,BA7,$AB$8:$AB$1039,AS14,$R$8:$R$1039,AR14)<=D86) -> TRUE | BB14: =AND(SUMIFS($AN$8:$AN$1039,$O$8:$O$1039,BB7,$AB$8:$AB$1039,AS14,$R$8:$R$1039,AR14)<=D92,SUMIFS($AO$8:$AO$1039,$O$8:$O$1039,BB7,$AB$8:$AB$1039,AS14,$R$8:$R$1039,AR14)<=D98) -> TRUE
B15: B+ | C15: 0 | D15: 0 | E15: 0 | O15: Q1’26 | P15: 1 | Q15: 3 | R15: 2 | T15: =(S14+S15+S16)=N2 -> FALSE | X15: =MAX(S12-S15,0) -> 0 | Y15: 0 | AA15: 8 | AB15: F | AC15: F+ | AD15: 27 | AE15: 23 | AF15: 0.8 | AG15: 0.9 | AH15: 0 | AI15: 0 | AJ15: =SUMIFS(AH$8:AH$1039,$O$8:$O$1039,O15,$AB$8:$AB$1039,AB15,$R$8:$R$1039,R15,$AA$8:$AA$1039,"<="&AA15) -> 0 | AK15: =D13 -> 60 | AL15: =D19 -> 0 | AM15: =MAX(0,AJ15-AK15) -> 0 | AN15: =IF(AM15=0,AH15,IF(AM15>=AH15,0,AH15-AM15)) -> 0 | AO15: =IF(AM15>=AH15,AI15,AI15*AM15/AH15) -> 0 | AP15: {=INDEX($AU$8:$BB$25,6*(R15-1)+MATCH(AB15,$AS$8:$AS$13,0),MATCH(O15,$AU$7:$BB$7,0))} -> TRUE | AR15: 2 | AS15: B | AT15: B+ | AU15: =AND(SUMIFS($AN$8:$AN$1039,$O$8:$O$1039,AU7,$AB$8:$AB$1039,AS15,$R$8:$R$1039,AR15)<=D9,SUMIFS($AO$8:$AO$1039,$O$8:$O$1039,AU7,$AB$8:$AB$1039,AS15,$R$8:$R$1039,AR15)<=D15) -> TRUE | AV15: =AND(SUMIFS($AN$8:$AN$1039,$O$8:$O$1039,AV7,$AB$8:$AB$1039,AS15,$R$8:$R$1039,AR15)<=D21,SUMIFS($AO$8:$AO$1039,$O$8:$O$1039,AV7,$AB$8:$AB$1039,AS15,$R$8:$R$1039,AR15)<=D27) -> TRUE | AW15: =AND(SUMIFS($AN$8:$AN$1039,$O$8:$O$1039,AW7,$AB$8:$AB$1039,AS15,$R$8:$R$1039,AR15)<=D33,SUMIFS($AO$8:$AO$1039,$O$8:$O$1039,AW7,$AB$8:$AB$1039,AS15,$R$8:$R$1039,AR15)<=D39) -> TRUE | AX15: =AND(SUMIFS($AN$8:$AN$1039,$O$8:$O$1039,AX7,$AB$8:$AB$1039,AS15,$R$8:$R$1039,AR15)<=D45,SUMIFS($AO$8:$AO$1039,$O$8:$O$1039,AX7,$AB$8:$AB$1039,AS15,$R$8:$R$1039,AR15)<=D51) -> TRUE | AY15: =AND(SUMIFS($AN$8:$AN$1039,$O$8:$O$1039,AY7,$AB$8:$AB$1039,AS15,$R$8:$R$1039,AR15)<=D57,SUMIFS($AO$8:$AO$1039,$O$8:$O$1039,AY7,$AB$8:$AB$1039,AS15,$R$8:$R$1039,AR15)<=D63) -> TRUE | AZ15: =AND(SUMIFS($AN$8:$AN$1039,$O$8:$O$1039,AZ7,$AB$8:$AB$1039,AS15,$R$8:$R$1039,AR15)<=D69,SUMIFS($AO$8:$AO$1039,$O$8:$O$1039,AZ7,$AB$8:$AB$1039,AS15,$R$8:$R$1039,AR15)<=D75) -> TRUE | BA15: =AND(SUMIFS($AN$8:$AN$1039,$O$8:$O$1039,BA7,$AB$8:$AB$1039,AS15,$R$8:$R$1039,AR15)<=D81,SUMIFS($AO$8:$AO$1039,$O$8:$O$1039,BA7,$AB$8:$AB$1039,AS15,$R$8:$R$1039,AR15)<=D87) -> TRUE | BB15: =AND(SUMIFS($AN$8:$AN$1039,$O$8:$O$1039,BB7,$AB$8:$AB$1039,AS15,$R$8:$R$1039,AR15)<=D93,SUMIFS($AO$8:$AO$1039,$O$8:$O$1039,BB7,$AB$8:$AB$1039,AS15,$R$8:$R$1039,AR15)<=D99) -> TRUE
B16: C+ | C16: 0 | D16: 0 | E16: 0 | O16: Q1’26 | P16: 1 | Q16: 3 | R16: 3 | T16: =(S14+S15+S16)=N2 -> FALSE | X16: =MAX(S13-S16,0) -> 0 | Y16: 0 | AA16: 8 | AB16: F | AC16: F+ | AD16: 27 | AE16: 23 | AF16: 0.8 | AG16: 0.9 | AH16: 0 | AI16: 0 | AJ16: =SUMIFS(AH$8:AH$1039,$O$8:$O$1039,O16,$AB$8:$AB$1039,AB16,$R$8:$R$1039,R16,$AA$8:$AA$1039,"<="&AA16) -> 0 | AK16: =E13 -> 36 | AL16: =E19 -> 0 | AM16: =MAX(0,AJ16-AK16) -> 0 | AN16: =IF(AM16=0,AH16,IF(AM16>=AH16,0,AH16-AM16)) -> 0 | AO16: =IF(AM16>=AH16,AI16,AI16*AM16/AH16) -> 0 | AP16: {=INDEX($AU$8:$BB$25,6*(R16-1)+MATCH(AB16,$AS$8:$AS$13,0),MATCH(O16,$AU$7:$BB$7,0))} -> TRUE | AR16: 2 | AS16: C | AT16: C+ | AU16: =AND(SUMIFS($AN$8:$AN$1039,$O$8:$O$1039,AU7,$AB$8:$AB$1039,AS16,$R$8:$R$1039,AR16)<=D10,SUMIFS($AO$8:$AO$1039,$O$8:$O$1039,AU7,$AB$8:$AB$1039,AS16,$R$8:$R$1039,AR16)<=D16) -> TRUE | AV16: =AND(SUMIFS($AN$8:$AN$1039,$O$8:$O$1039,AV7,$AB$8:$AB$1039,AS16,$R$8:$R$1039,AR16)<=D22,SUMIFS($AO$8:$AO$1039,$O$8:$O$1039,AV7,$AB$8:$AB$1039,AS16,$R$8:$R$1039,AR16)<=D28) -> TRUE | AW16: =AND(SUMIFS($AN$8:$AN$1039,$O$8:$O$1039,AW7,$AB$8:$AB$1039,AS16,$R$8:$R$1039,AR16)<=D34,SUMIFS($AO$8:$AO$1039,$O$8:$O$1039,AW7,$AB$8:$AB$1039,AS16,$R$8:$R$1039,AR16)<=D40) -> TRUE | AX16: =AND(SUMIFS($AN$8:$AN$1039,$O$8:$O$1039,AX7,$AB$8:$AB$1039,AS16,$R$8:$R$1039,AR16)<=D46,SUMIFS($AO$8:$AO$1039,$O$8:$O$1039,AX7,$AB$8:$AB$1039,AS16,$R$8:$R$1039,AR16)<=D52) -> TRUE | AY16: =AND(SUMIFS($AN$8:$AN$1039,$O$8:$O$1039,AY7,$AB$8:$AB$1039,AS16,$R$8:$R$1039,AR16)<=D58,SUMIFS($AO$8:$AO$1039,$O$8:$O$1039,AY7,$AB$8:$AB$1039,AS16,$R$8:$R$1039,AR16)<=D64) -> TRUE | AZ16: =AND(SUMIFS($AN$8:$AN$1039,$O$8:$O$1039,AZ7,$AB$8:$AB$1039,AS16,$R$8:$R$1039,AR16)<=D70,SUMIFS($AO$8:$AO$1039,$O$8:$O$1039,AZ7,$AB$8:$AB$1039,AS16,$R$8:$R$1039,AR16)<=D76) -> TRUE | BA16: =AND(SUMIFS($AN$8:$AN$1039,$O$8:$O$1039,BA7,$AB$8:$AB$1039,AS16,$R$8:$R$1039,AR16)<=D82,SUMIFS($AO$8:$AO$1039,$O$8:$O$1039,BA7,$AB$8:$AB$1039,AS16,$R$8:$R$1039,AR16)<=D88) -> TRUE | BB16: =AND(SUMIFS($AN$8:$AN$1039,$O$8:$O$1039,BB7,$AB$8:$AB$1039,AS16,$R$8:$R$1039,AR16)<=D94,SUMIFS($AO$8:$AO$1039,$O$8:$O$1039,BB7,$AB$8:$AB$1039,AS16,$R$8:$R$1039,AR16)<=D100) -> TRUE
B17: D+ | C17: 0 | D17: 0 | E17: 0 | O17: Q1’26 | P17: 1 | Q17: 4 | R17: 1 | T17: =(S17+S18+S19)=N2 -> FALSE | X17: =MAX(S14-S17,0) -> 0 | Y17: 0 | AA17: 3 | AB17: A | AC17: A+ | AD17: 20 | AE17: 16 | AF17: 0.78 | AG17: 0.84 | AH17: 0 | AI17: 0 | AJ17: =SUMIFS(AH$8:AH$1039,$O$8:$O$1039,O17,$AB$8:$AB$1039,AB17,$R$8:$R$1039,R17,$AA$8:$AA$1039,"<="&AA17) -> 0 | AK17: =C8 -> 50 | AL17: =C14 -> 0 | AM17: =MAX(0,AJ17-AK17) -> 0 | AN17: =IF(AM17=0,AH17,IF(AM17>=AH17,0,AH17-AM17)) -> 0 | AO17: =IF(AM17>=AH17,AI17,AI17*AM17/AH17) -> 0 | AP17: {=INDEX($AU$8:$BB$25,6*(R17-1)+MATCH(AB17,$AS$8:$AS$13,0),MATCH(O17,$AU$7:$BB$7,0))} -> TRUE | AR17: 2 | AS17: D | AT17: D+ | AU17: =AND(SUMIFS($AN$8:$AN$1039,$O$8:$O$1039,AU7,$AB$8:$AB$1039,AS17,$R$8:$R$1039,AR17)<=D11,SUMIFS($AO$8:$AO$1039,$O$8:$O$1039,AU7,$AB$8:$AB$1039,AS17,$R$8:$R$1039,AR17)<=D17) -> TRUE | AV17: =AND(SUMIFS($AN$8:$AN$1039,$O$8:$O$1039,AV7,$AB$8:$AB$1039,AS17,$R$8:$R$1039,AR17)<=D23,SUMIFS($AO$8:$AO$1039,$O$8:$O$1039,AV7,$AB$8:$AB$1039,AS17,$R$8:$R$1039,AR17)<=D29) -> TRUE | AW17: =AND(SUMIFS($AN$8:$AN$1039,$O$8:$O$1039,AW7,$AB$8:$AB$1039,AS17,$R$8:$R$1039,AR17)<=D35,SUMIFS($AO$8:$AO$1039,$O$8:$O$1039,AW7,$AB$8:$AB$1039,AS17,$R$8:$R$1039,AR17)<=D41) -> TRUE | AX17: =AND(SUMIFS($AN$8:$AN$1039,$O$8:$O$1039,AX7,$AB$8:$AB$1039,AS17,$R$8:$R$1039,AR17)<=D47,SUMIFS($AO$8:$AO$1039,$O$8:$O$1039,AX7,$AB$8:$AB$1039,AS17,$R$8:$R$1039,AR17)<=D53) -> TRUE | AY17: =AND(SUMIFS($AN$8:$AN$1039,$O$8:$O$1039,AY7,$AB$8:$AB$1039,AS17,$R$8:$R$1039,AR17)<=D59,SUMIFS($AO$8:$AO$1039,$O$8:$O$1039,AY7,$AB$8:$AB$1039,AS17,$R$8:$R$1039,AR17)<=D65) -> TRUE | AZ17: =AND(SUMIFS($AN$8:$AN$1039,$O$8:$O$1039,AZ7,$AB$8:$AB$1039,AS17,$R$8:$R$1039,AR17)<=D71,SUMIFS($AO$8:$AO$1039,$O$8:$O$1039,AZ7,$AB$8:$AB$1039,AS17,$R$8:$R$1039,AR17)<=D77) -> TRUE | BA17: =AND(SUMIFS($AN$8:$AN$1039,$O$8:$O$1039,BA7,$AB$8:$AB$1039,AS17,$R$8:$R$1039,AR17)<=D83,SUMIFS($AO$8:$AO$1039,$O$8:$O$1039,BA7,$AB$8:$AB$1039,AS17,$R$8:$R$1039,AR17)<=D89) -> TRUE | BB17: =AND(SUMIFS($AN$8:$AN$1039,$O$8:$O$1039,BB7,$AB$8:$AB$1039,AS17,$R$8:$R$1039,AR17)<=D95,SUMIFS($AO$8:$AO$1039,$O$8:$O$1039,BB7,$AB$8:$AB$1039,AS17,$R$8:$R$1039,AR17)<=D101) -> TRUE
B18: E+ | C18: 0 | D18: 0 | E18: 0 | O18: Q1’26 | P18: 1 | Q18: 4 | R18: 2 | T18: =(S17+S18+S19)=N2 -> FALSE | X18: =MAX(S15-S18,0) -> 0 | Y18: 0 | AA18: 3 | AB18: A | AC18: A+ | AD18: 20 | AE18: 16 | AF18: 0.78 | AG18: 0.84 | AH18: 0 | AI18: 0 | AJ18: =SUMIFS(AH$8:AH$1039,$O$8:$O$1039,O18,$AB$8:$AB$1039,AB18,$R$8:$R$1039,R18,$AA$8:$AA$1039,"<="&AA18) -> 0 | AK18: =D8 -> 35 | AL18: =D14 -> 0 | AM18: =MAX(0,AJ18-AK18) -> 0 | AN18: =IF(AM18=0,AH18,IF(AM18>=AH18,0,AH18-AM18)) -> 0 | AO18: =IF(AM18>=AH18,AI18,AI18*AM18/AH18) -> 0 | AP18: {=INDEX($AU$8:$BB$25,6*(R18-1)+MATCH(AB18,$AS$8:$AS$13,0),MATCH(O18,$AU$7:$BB$7,0))} -> TRUE | AR18: 2 | AS18: E | AT18: E+ | AU18: =AND(SUMIFS($AN$8:$AN$1039,$O$8:$O$1039,AU7,$AB$8:$AB$1039,AS18,$R$8:$R$1039,AR18)<=D12,SUMIFS($AO$8:$AO$1039,$O$8:$O$1039,AU7,$AB$8:$AB$1039,AS18,$R$8:$R$1039,AR18)<=D18) -> TRUE | AV18: =AND(SUMIFS($AN$8:$AN$1039,$O$8:$O$1039,AV7,$AB$8:$AB$1039,AS18,$R$8:$R$1039,AR18)<=D24,SUMIFS($AO$8:$AO$1039,$O$8:$O$1039,AV7,$AB$8:$AB$1039,AS18,$R$8:$R$1039,AR18)<=D30) -> TRUE | AW18: =AND(SUMIFS($AN$8:$AN$1039,$O$8:$O$1039,AW7,$AB$8:$AB$1039,AS18,$R$8:$R$1039,AR18)<=D36,SUMIFS($AO$8:$AO$1039,$O$8:$O$1039,AW7,$AB$8:$AB$1039,AS18,$R$8:$R$1039,AR18)<=D42) -> TRUE | AX18: =AND(SUMIFS($AN$8:$AN$1039,$O$8:$O$1039,AX7,$AB$8:$AB$1039,AS18,$R$8:$R$1039,AR18)<=D48,SUMIFS($AO$8:$AO$1039,$O$8:$O$1039,AX7,$AB$8:$AB$1039,AS18,$R$8:$R$1039,AR18)<=D54) -> TRUE | AY18: =AND(SUMIFS($AN$8:$AN$1039,$O$8:$O$1039,AY7,$AB$8:$AB$1039,AS18,$R$8:$R$1039,AR18)<=D60,SUMIFS($AO$8:$AO$1039,$O$8:$O$1039,AY7,$AB$8:$AB$1039,AS18,$R$8:$R$1039,AR18)<=D66) -> TRUE | AZ18: =AND(SUMIFS($AN$8:$AN$1039,$O$8:$O$1039,AZ7,$AB$8:$AB$1039,AS18,$R$8:$R$1039,AR18)<=D72,SUMIFS($AO$8:$AO$1039,$O$8:$O$1039,AZ7,$AB$8:$AB$1039,AS18,$R$8:$R$1039,AR18)<=D78) -> TRUE | BA18: =AND(SUMIFS($AN$8:$AN$1039,$O$8:$O$1039,BA7,$AB$8:$AB$1039,AS18,$R$8:$R$1039,AR18)<=D84,SUMIFS($AO$8:$AO$1039,$O$8:$O$1039,BA7,$AB$8:$AB$1039,AS18,$R$8:$R$1039,AR18)<=D90) -> TRUE | BB18: =AND(SUMIFS($AN$8:$AN$1039,$O$8:$O$1039,BB7,$AB$8:$AB$1039,AS18,$R$8:$R$1039,AR18)<=D96,SUMIFS($AO$8:$AO$1039,$O$8:$O$1039,BB7,$AB$8:$AB$1039,AS18,$R$8:$R$1039,AR18)<=D102) -> TRUE
B19: F+ | C19: 0 | D19: 0 | E19: 0 | F19: Fab 1 space | G19: Fab 2 space | H19: Fab 3 space | O19: Q1’26 | P19: 1 | Q19: 4 | R19: 3 | T19: =(S17+S18+S19)=N2 -> FALSE | X19: =MAX(S16-S19,0) -> 0 | Y19: 0 | AA19: 3 | AB19: A | AC19: A+ | AD19: 20 | AE19: 16 | AF19: 0.78 | AG19: 0.84 | AH19: 0 | AI19: 0 | AJ19: =SUMIFS(AH$8:AH$1039,$O$8:$O$1039,O19,$AB$8:$AB$1039,AB19,$R$8:$R$1039,R19,$AA$8:$AA$1039,"<="&AA19) -> 0 | AK19: =E8 -> 0 | AL19: =E14 -> 0 | AM19: =MAX(0,AJ19-AK19) -> 0 | AN19: =IF(AM19=0,AH19,IF(AM19>=AH19,0,AH19-AM19)) -> 0 | AO19: =IF(AM19>=AH19,AI19,AI19*AM19/AH19) -> 0 | AP19: {=INDEX($AU$8:$BB$25,6*(R19-1)+MATCH(AB19,$AS$8:$AS$13,0),MATCH(O19,$AU$7:$BB$7,0))} -> TRUE | AR19: 2 | AS19: F | AT19: F+ | AU19: =AND(SUMIFS($AN$8:$AN$1039,$O$8:$O$1039,AU7,$AB$8:$AB$1039,AS19,$R$8:$R$1039,AR19)<=D13,SUMIFS($AO$8:$AO$1039,$O$8:$O$1039,AU7,$AB$8:$AB$1039,AS19,$R$8:$R$1039,AR19)<=D19) -> TRUE | AV19: =AND(SUMIFS($AN$8:$AN$1039,$O$8:$O$1039,AV7,$AB$8:$AB$1039,AS19,$R$8:$R$1039,AR19)<=D25,SUMIFS($AO$8:$AO$1039,$O$8:$O$1039,AV7,$AB$8:$AB$1039,AS19,$R$8:$R$1039,AR19)<=D31) -> TRUE | AW19: =AND(SUMIFS($AN$8:$AN$1039,$O$8:$O$1039,AW7,$AB$8:$AB$1039,AS19,$R$8:$R$1039,AR19)<=D37,SUMIFS($AO$8:$AO$1039,$O$8:$O$1039,AW7,$AB$8:$AB$1039,AS19,$R$8:$R$1039,AR19)<=D43) -> TRUE | AX19: =AND(SUMIFS($AN$8:$AN$1039,$O$8:$O$1039,AX7,$AB$8:$AB$1039,AS19,$R$8:$R$1039,AR19)<=D49,SUMIFS($AO$8:$AO$1039,$O$8:$O$1039,AX7,$AB$8:$AB$1039,AS19,$R$8:$R$1039,AR19)<=D55) -> TRUE | AY19: =AND(SUMIFS($AN$8:$AN$1039,$O$8:$O$1039,AY7,$AB$8:$AB$1039,AS19,$R$8:$R$1039,AR19)<=D61,SUMIFS($AO$8:$AO$1039,$O$8:$O$1039,AY7,$AB$8:$AB$1039,AS19,$R$8:$R$1039,AR19)<=D67) -> TRUE | AZ19: =AND(SUMIFS($AN$8:$AN$1039,$O$8:$O$1039,AZ7,$AB$8:$AB$1039,AS19,$R$8:$R$1039,AR19)<=D73,SUMIFS($AO$8:$AO$1039,$O$8:$O$1039,AZ7,$AB$8:$AB$1039,AS19,$R$8:$R$1039,AR19)<=D79) -> TRUE | BA19: =AND(SUMIFS($AN$8:$AN$1039,$O$8:$O$1039,BA7,$AB$8:$AB$1039,AS19,$R$8:$R$1039,AR19)<=D85,SUMIFS($AO$8:$AO$1039,$O$8:$O$1039,BA7,$AB$8:$AB$1039,AS19,$R$8:$R$1039,AR19)<=D91) -> TRUE | BB19: =AND(SUMIFS($AN$8:$AN$1039,$O$8:$O$1039,BB7,$AB$8:$AB$1039,AS19,$R$8:$R$1039,AR19)<=D97,SUMIFS($AO$8:$AO$1039,$O$8:$O$1039,BB7,$AB$8:$AB$1039,AS19,$R$8:$R$1039,AR19)<=D103) -> TRUE
A20: WS Component for Q2’26 | B20: A | F20: {=SUM(C20:C31*data!$B$3:$B$14)} -> 0 | G20: {=SUM(D20:D31*data!$B$3:$B$14)} -> 0 | H20: {=SUM(E20:E31*data!$B$3:$B$14)} -> 0 | I20: <- make sure its green | O20: Q1’26 | P20: 1 | Q20: 5 | R20: 1 | T20: =(S20+S21+S22)=N2 -> FALSE | X20: =MAX(S17-S20,0) -> 0 | Y20: 0 | AA20: 11 | AB20: F | AC20: F+ | AD20: 12 | AE20: 9 | AF20: 0.8 | AG20: 0.9 | AH20: 0 | AI20: 0 | AJ20: =SUMIFS(AH$8:AH$1039,$O$8:$O$1039,O20,$AB$8:$AB$1039,AB20,$R$8:$R$1039,R20,$AA$8:$AA$1039,"<="&AA20) -> 0 | AK20: =C13 -> 90 | AL20: =C19 -> 0 | AM20: =MAX(0,AJ20-AK20) -> 0 | AN20: =IF(AM20=0,AH20,IF(AM20>=AH20,0,AH20-AM20)) -> 0 | AO20: =IF(AM20>=AH20,AI20,AI20*AM20/AH20) -> 0 | AP20: {=INDEX($AU$8:$BB$25,6*(R20-1)+MATCH(AB20,$AS$8:$AS$13,0),MATCH(O20,$AU$7:$BB$7,0))} -> TRUE | AR20: 3 | AS20: A | AT20: A+ | AU20: =AND(SUMIFS($AN$8:$AN$1039,$O$8:$O$1039,AU7,$AB$8:$AB$1039,AS20,$R$8:$R$1039,AR20)<=E8,SUMIFS($AO$8:$AO$1039,$O$8:$O$1039,AU7,$AB$8:$AB$1039,AS20,$R$8:$R$1039,AR20)<=E14) -> TRUE | AV20: =AND(SUMIFS($AN$8:$AN$1039,$O$8:$O$1039,AV7,$AB$8:$AB$1039,AS20,$R$8:$R$1039,AR20)<=E20,SUMIFS($AO$8:$AO$1039,$O$8:$O$1039,AV7,$AB$8:$AB$1039,AS20,$R$8:$R$1039,AR20)<=E26) -> TRUE | AW20: =AND(SUMIFS($AN$8:$AN$1039,$O$8:$O$1039,AW7,$AB$8:$AB$1039,AS20,$R$8:$R$1039,AR20)<=E32,SUMIFS($AO$8:$AO$1039,$O$8:$O$1039,AW7,$AB$8:$AB$1039,AS20,$R$8:$R$1039,AR20)<=E38) -> TRUE | AX20: =AND(SUMIFS($AN$8:$AN$1039,$O$8:$O$1039,AX7,$AB$8:$AB$1039,AS20,$R$8:$R$1039,AR20)<=E44,SUMIFS($AO$8:$AO$1039,$O$8:$O$1039,AX7,$AB$8:$AB$1039,AS20,$R$8:$R$1039,AR20)<=E50) -> TRUE | AY20: =AND(SUMIFS($AN$8:$AN$1039,$O$8:$O$1039,AY7,$AB$8:$AB$1039,AS20,$R$8:$R$1039,AR20)<=E56,SUMIFS($AO$8:$AO$1039,$O$8:$O$1039,AY7,$AB$8:$AB$1039,AS20,$R$8:$R$1039,AR20)<=E62) -> TRUE | AZ20: =AND(SUMIFS($AN$8:$AN$1039,$O$8:$O$1039,AZ7,$AB$8:$AB$1039,AS20,$R$8:$R$1039,AR20)<=E68,SUMIFS($AO$8:$AO$1039,$O$8:$O$1039,AZ7,$AB$8:$AB$1039,AS20,$R$8:$R$1039,AR20)<=E74) -> TRUE | BA20: =AND(SUMIFS($AN$8:$AN$1039,$O$8:$O$1039,BA7,$AB$8:$AB$1039,AS20,$R$8:$R$1039,AR20)<=E80,SUMIFS($AO$8:$AO$1039,$O$8:$O$1039,BA7,$AB$8:$AB$1039,AS20,$R$8:$R$1039,AR20)<=E86) -> TRUE | BB20: =AND(SUMIFS($AN$8:$AN$1039,$O$8:$O$1039,BB7,$AB$8:$AB$1039,AS20,$R$8:$R$1039,AR20)<=E92,SUMIFS($AO$8:$AO$1039,$O$8:$O$1039,BB7,$AB$8:$AB$1039,AS20,$R$8:$R$1039,AR20)<=E98) -> TRUE
B21: B | O21: Q1’26 | P21: 1 | Q21: 5 | R21: 2 | T21: =(S20+S21+S22)=N2 -> FALSE | X21: =MAX(S18-S21,0) -> 0 | Y21: 0 | AA21: 11 | AB21: F | AC21: F+ | AD21: 12 | AE21: 9 | AF21: 0.8 | AG21: 0.9 | AH21: 0 | AI21: 0 | AJ21: =SUMIFS(AH$8:AH$1039,$O$8:$O$1039,O21,$AB$8:$AB$1039,AB21,$R$8:$R$1039,R21,$AA$8:$AA$1039,"<="&AA21) -> 0 | AK21: =D13 -> 60 | AL21: =D19 -> 0 | AM21: =MAX(0,AJ21-AK21) -> 0 | AN21: =IF(AM21=0,AH21,IF(AM21>=AH21,0,AH21-AM21)) -> 0 | AO21: =IF(AM21>=AH21,AI21,AI21*AM21/AH21) -> 0 | AP21: {=INDEX($AU$8:$BB$25,6*(R21-1)+MATCH(AB21,$AS$8:$AS$13,0),MATCH(O21,$AU$7:$BB$7,0))} -> TRUE | AR21: 3 | AS21: B | AT21: B+ | AU21: =AND(SUMIFS($AN$8:$AN$1039,$O$8:$O$1039,AU7,$AB$8:$AB$1039,AS21,$R$8:$R$1039,AR21)<=E9,SUMIFS($AO$8:$AO$1039,$O$8:$O$1039,AU7,$AB$8:$AB$1039,AS21,$R$8:$R$1039,AR21)<=E15) -> TRUE | AV21: =AND(SUMIFS($AN$8:$AN$1039,$O$8:$O$1039,AV7,$AB$8:$AB$1039,AS21,$R$8:$R$1039,AR21)<=E21,SUMIFS($AO$8:$AO$1039,$O$8:$O$1039,AV7,$AB$8:$AB$1039,AS21,$R$8:$R$1039,AR21)<=E27) -> TRUE | AW21: =AND(SUMIFS($AN$8:$AN$1039,$O$8:$O$1039,AW7,$AB$8:$AB$1039,AS21,$R$8:$R$1039,AR21)<=E33,SUMIFS($AO$8:$AO$1039,$O$8:$O$1039,AW7,$AB$8:$AB$1039,AS21,$R$8:$R$1039,AR21)<=E39) -> TRUE | AX21: =AND(SUMIFS($AN$8:$AN$1039,$O$8:$O$1039,AX7,$AB$8:$AB$1039,AS21,$R$8:$R$1039,AR21)<=E45,SUMIFS($AO$8:$AO$1039,$O$8:$O$1039,AX7,$AB$8:$AB$1039,AS21,$R$8:$R$1039,AR21)<=E51) -> TRUE | AY21: =AND(SUMIFS($AN$8:$AN$1039,$O$8:$O$1039,AY7,$AB$8:$AB$1039,AS21,$R$8:$R$1039,AR21)<=E57,SUMIFS($AO$8:$AO$1039,$O$8:$O$1039,AY7,$AB$8:$AB$1039,AS21,$R$8:$R$1039,AR21)<=E63) -> TRUE | AZ21: =AND(SUMIFS($AN$8:$AN$1039,$O$8:$O$1039,AZ7,$AB$8:$AB$1039,AS21,$R$8:$R$1039,AR21)<=E69,SUMIFS($AO$8:$AO$1039,$O$8:$O$1039,AZ7,$AB$8:$AB$1039,AS21,$R$8:$R$1039,AR21)<=E75) -> TRUE | BA21: =AND(SUMIFS($AN$8:$AN$1039,$O$8:$O$1039,BA7,$AB$8:$AB$1039,AS21,$R$8:$R$1039,AR21)<=E81,SUMIFS($AO$8:$AO$1039,$O$8:$O$1039,BA7,$AB$8:$AB$1039,AS21,$R$8:$R$1039,AR21)<=E87) -> TRUE | BB21: =AND(SUMIFS($AN$8:$AN$1039,$O$8:$O$1039,BB7,$AB$8:$AB$1039,AS21,$R$8:$R$1039,AR21)<=E93,SUMIFS($AO$8:$AO$1039,$O$8:$O$1039,BB7,$AB$8:$AB$1039,AS21,$R$8:$R$1039,AR21)<=E99) -> TRUE
B22: C | F22: New tool purchase cost | O22: Q1’26 | P22: 1 | Q22: 5 | R22: 3 | T22: =(S20+S21+S22)=N2 -> FALSE | X22: =MAX(S19-S22,0) -> 0 | Y22: 0 | AA22: 11 | AB22: F | AC22: F+ | AD22: 12 | AE22: 9 | AF22: 0.8 | AG22: 0.9 | AH22: 0 | AI22: 0 | AJ22: =SUMIFS(AH$8:AH$1039,$O$8:$O$1039,O22,$AB$8:$AB$1039,AB22,$R$8:$R$1039,R22,$AA$8:$AA$1039,"<="&AA22) -> 0 | AK22: =E13 -> 36 | AL22: =E19 -> 0 | AM22: =MAX(0,AJ22-AK22) -> 0 | AN22: =IF(AM22=0,AH22,IF(AM22>=AH22,0,AH22-AM22)) -> 0 | AO22: =IF(AM22>=AH22,AI22,AI22*AM22/AH22) -> 0 | AP22: {=INDEX($AU$8:$BB$25,6*(R22-1)+MATCH(AB22,$AS$8:$AS$13,0),MATCH(O22,$AU$7:$BB$7,0))} -> TRUE | AR22: 3 | AS22: C | AT22: C+ | AU22: =AND(SUMIFS($AN$8:$AN$1039,$O$8:$O$1039,AU7,$AB$8:$AB$1039,AS22,$R$8:$R$1039,AR22)<=E10,SUMIFS($AO$8:$AO$1039,$O$8:$O$1039,AU7,$AB$8:$AB$1039,AS22,$R$8:$R$1039,AR22)<=E16) -> TRUE | AV22: =AND(SUMIFS($AN$8:$AN$1039,$O$8:$O$1039,AV7,$AB$8:$AB$1039,AS22,$R$8:$R$1039,AR22)<=E22,SUMIFS($AO$8:$AO$1039,$O$8:$O$1039,AV7,$AB$8:$AB$1039,AS22,$R$8:$R$1039,AR22)<=E28) -> TRUE | AW22: =AND(SUMIFS($AN$8:$AN$1039,$O$8:$O$1039,AW7,$AB$8:$AB$1039,AS22,$R$8:$R$1039,AR22)<=E34,SUMIFS($AO$8:$AO$1039,$O$8:$O$1039,AW7,$AB$8:$AB$1039,AS22,$R$8:$R$1039,AR22)<=E40) -> TRUE | AX22: =AND(SUMIFS($AN$8:$AN$1039,$O$8:$O$1039,AX7,$AB$8:$AB$1039,AS22,$R$8:$R$1039,AR22)<=E46,SUMIFS($AO$8:$AO$1039,$O$8:$O$1039,AX7,$AB$8:$AB$1039,AS22,$R$8:$R$1039,AR22)<=E52) -> TRUE | AY22: =AND(SUMIFS($AN$8:$AN$1039,$O$8:$O$1039,AY7,$AB$8:$AB$1039,AS22,$R$8:$R$1039,AR22)<=E58,SUMIFS($AO$8:$AO$1039,$O$8:$O$1039,AY7,$AB$8:$AB$1039,AS22,$R$8:$R$1039,AR22)<=E64) -> TRUE | AZ22: =AND(SUMIFS($AN$8:$AN$1039,$O$8:$O$1039,AZ7,$AB$8:$AB$1039,AS22,$R$8:$R$1039,AR22)<=E70,SUMIFS($AO$8:$AO$1039,$O$8:$O$1039,AZ7,$AB$8:$AB$1039,AS22,$R$8:$R$1039,AR22)<=E76) -> TRUE | BA22: =AND(SUMIFS($AN$8:$AN$1039,$O$8:$O$1039,BA7,$AB$8:$AB$1039,AS22,$R$8:$R$1039,AR22)<=E82,SUMIFS($AO$8:$AO$1039,$O$8:$O$1039,BA7,$AB$8:$AB$1039,AS22,$R$8:$R$1039,AR22)<=E88) -> TRUE | BB22: =AND(SUMIFS($AN$8:$AN$1039,$O$8:$O$1039,BB7,$AB$8:$AB$1039,AS22,$R$8:$R$1039,AR22)<=E94,SUMIFS($AO$8:$AO$1039,$O$8:$O$1039,BB7,$AB$8:$AB$1039,AS22,$R$8:$R$1039,AR22)<=E100) -> TRUE
B23: D | F23: {=SUM( _xlfn.BYROW( IF(C20:E31-C8:E19>0, C20:E31-C8:E19, 0), _xleta.SUM) *data!$C$3:$C$14 )} -> 0 | O23: Q1’26 | P23: 1 | Q23: 6 | R23: 1 | T23: =(S23+S24+S25)=N2 -> FALSE | X23: =MAX(S20-S23,0) -> 0 | Y23: 0 | AA23: 7 | AB23: D | AC23: D+ | AD23: 27 | AE23: 21 | AF23: 0.8 | AG23: 0.88 | AH23: 0 | AI23: 0 | AJ23: =SUMIFS(AH$8:AH$1039,$O$8:$O$1039,O23,$AB$8:$AB$1039,AB23,$R$8:$R$1039,R23,$AA$8:$AA$1039,"<="&AA23) -> 0 | AK23: =C11 -> 50 | AL23: =C17 -> 0 | AM23: =MAX(0,AJ23-AK23) -> 0 | AN23: =IF(AM23=0,AH23,IF(AM23>=AH23,0,AH23-AM23)) -> 0 | AO23: =IF(AM23>=AH23,AI23,AI23*AM23/AH23) -> 0 | AP23: {=INDEX($AU$8:$BB$25,6*(R23-1)+MATCH(AB23,$AS$8:$AS$13,0),MATCH(O23,$AU$7:$BB$7,0))} -> TRUE | AR23: 3 | AS23: D | AT23: D+ | AU23: =AND(SUMIFS($AN$8:$AN$1039,$O$8:$O$1039,AU7,$AB$8:$AB$1039,AS23,$R$8:$R$1039,AR23)<=E11,SUMIFS($AO$8:$AO$1039,$O$8:$O$1039,AU7,$AB$8:$AB$1039,AS23,$R$8:$R$1039,AR23)<=E17) -> TRUE | AV23: =AND(SUMIFS($AN$8:$AN$1039,$O$8:$O$1039,AV7,$AB$8:$AB$1039,AS23,$R$8:$R$1039,AR23)<=E23,SUMIFS($AO$8:$AO$1039,$O$8:$O$1039,AV7,$AB$8:$AB$1039,AS23,$R$8:$R$1039,AR23)<=E29) -> TRUE | AW23: =AND(SUMIFS($AN$8:$AN$1039,$O$8:$O$1039,AW7,$AB$8:$AB$1039,AS23,$R$8:$R$1039,AR23)<=E35,SUMIFS($AO$8:$AO$1039,$O$8:$O$1039,AW7,$AB$8:$AB$1039,AS23,$R$8:$R$1039,AR23)<=E41) -> TRUE | AX23: =AND(SUMIFS($AN$8:$AN$1039,$O$8:$O$1039,AX7,$AB$8:$AB$1039,AS23,$R$8:$R$1039,AR23)<=E47,SUMIFS($AO$8:$AO$1039,$O$8:$O$1039,AX7,$AB$8:$AB$1039,AS23,$R$8:$R$1039,AR23)<=E53) -> TRUE | AY23: =AND(SUMIFS($AN$8:$AN$1039,$O$8:$O$1039,AY7,$AB$8:$AB$1039,AS23,$R$8:$R$1039,AR23)<=E59,SUMIFS($AO$8:$AO$1039,$O$8:$O$1039,AY7,$AB$8:$AB$1039,AS23,$R$8:$R$1039,AR23)<=E65) -> TRUE | AZ23: =AND(SUMIFS($AN$8:$AN$1039,$O$8:$O$1039,AZ7,$AB$8:$AB$1039,AS23,$R$8:$R$1039,AR23)<=E71,SUMIFS($AO$8:$AO$1039,$O$8:$O$1039,AZ7,$AB$8:$AB$1039,AS23,$R$8:$R$1039,AR23)<=E77) -> TRUE | BA23: =AND(SUMIFS($AN$8:$AN$1039,$O$8:$O$1039,BA7,$AB$8:$AB$1039,AS23,$R$8:$R$1039,AR23)<=E83,SUMIFS($AO$8:$AO$1039,$O$8:$O$1039,BA7,$AB$8:$AB$1039,AS23,$R$8:$R$1039,AR23)<=E89) -> TRUE | BB23: =AND(SUMIFS($AN$8:$AN$1039,$O$8:$O$1039,BB7,$AB$8:$AB$1039,AS23,$R$8:$R$1039,AR23)<=E95,SUMIFS($AO$8:$AO$1039,$O$8:$O$1039,BB7,$AB$8:$AB$1039,AS23,$R$8:$R$1039,AR23)<=E101) -> TRUE
B24: E | F24: Moveout cost | O24: Q1’26 | P24: 1 | Q24: 6 | R24: 2 | T24: =(S23+S24+S25)=N2 -> FALSE | X24: =MAX(S21-S24,0) -> 0 | Y24: 0 | AA24: 7 | AB24: D | AC24: D+ | AD24: 27 | AE24: 21 | AF24: 0.8 | AG24: 0.88 | AH24: 0 | AI24: 0 | AJ24: =SUMIFS(AH$8:AH$1039,$O$8:$O$1039,O24,$AB$8:$AB$1039,AB24,$R$8:$R$1039,R24,$AA$8:$AA$1039,"<="&AA24) -> 0 | AK24: =D11 -> 50 | AL24: =D17 -> 0 | AM24: =MAX(0,AJ24-AK24) -> 0 | AN24: =IF(AM24=0,AH24,IF(AM24>=AH24,0,AH24-AM24)) -> 0 | AO24: =IF(AM24>=AH24,AI24,AI24*AM24/AH24) -> 0 | AP24: {=INDEX($AU$8:$BB$25,6*(R24-1)+MATCH(AB24,$AS$8:$AS$13,0),MATCH(O24,$AU$7:$BB$7,0))} -> TRUE | AR24: 3 | AS24: E | AT24: E+ | AU24: =AND(SUMIFS($AN$8:$AN$1039,$O$8:$O$1039,AU7,$AB$8:$AB$1039,AS24,$R$8:$R$1039,AR24)<=E12,SUMIFS($AO$8:$AO$1039,$O$8:$O$1039,AU7,$AB$8:$AB$1039,AS24,$R$8:$R$1039,AR24)<=E18) -> TRUE | AV24: =AND(SUMIFS($AN$8:$AN$1039,$O$8:$O$1039,AV7,$AB$8:$AB$1039,AS24,$R$8:$R$1039,AR24)<=E24,SUMIFS($AO$8:$AO$1039,$O$8:$O$1039,AV7,$AB$8:$AB$1039,AS24,$R$8:$R$1039,AR24)<=E30) -> TRUE | AW24: =AND(SUMIFS($AN$8:$AN$1039,$O$8:$O$1039,AW7,$AB$8:$AB$1039,AS24,$R$8:$R$1039,AR24)<=E36,SUMIFS($AO$8:$AO$1039,$O$8:$O$1039,AW7,$AB$8:$AB$1039,AS24,$R$8:$R$1039,AR24)<=E42) -> TRUE | AX24: =AND(SUMIFS($AN$8:$AN$1039,$O$8:$O$1039,AX7,$AB$8:$AB$1039,AS24,$R$8:$R$1039,AR24)<=E48,SUMIFS($AO$8:$AO$1039,$O$8:$O$1039,AX7,$AB$8:$AB$1039,AS24,$R$8:$R$1039,AR24)<=E54) -> TRUE | AY24: =AND(SUMIFS($AN$8:$AN$1039,$O$8:$O$1039,AY7,$AB$8:$AB$1039,AS24,$R$8:$R$1039,AR24)<=E60,SUMIFS($AO$8:$AO$1039,$O$8:$O$1039,AY7,$AB$8:$AB$1039,AS24,$R$8:$R$1039,AR24)<=E66) -> TRUE | AZ24: =AND(SUMIFS($AN$8:$AN$1039,$O$8:$O$1039,AZ7,$AB$8:$AB$1039,AS24,$R$8:$R$1039,AR24)<=E72,SUMIFS($AO$8:$AO$1039,$O$8:$O$1039,AZ7,$AB$8:$AB$1039,AS24,$R$8:$R$1039,AR24)<=E78) -> TRUE | BA24: =AND(SUMIFS($AN$8:$AN$1039,$O$8:$O$1039,BA7,$AB$8:$AB$1039,AS24,$R$8:$R$1039,AR24)<=E84,SUMIFS($AO$8:$AO$1039,$O$8:$O$1039,BA7,$AB$8:$AB$1039,AS24,$R$8:$R$1039,AR24)<=E90) -> TRUE | BB24: =AND(SUMIFS($AN$8:$AN$1039,$O$8:$O$1039,BB7,$AB$8:$AB$1039,AS24,$R$8:$R$1039,AR24)<=E96,SUMIFS($AO$8:$AO$1039,$O$8:$O$1039,BB7,$AB$8:$AB$1039,AS24,$R$8:$R$1039,AR24)<=E102) -> TRUE
B25: F | F25: {=SUM( _xlfn.BYROW( IF(C20:E31-C8:E19<0, C20:E31-C8:E19, 0), _xleta.SUM) * -1000000 )} -> 587000000 | O25: Q1’26 | P25: 1 | Q25: 6 | R25: 3 | T25: =(S23+S24+S25)=N2 -> FALSE | X25: =MAX(S22-S25,0) -> 0 | Y25: 0 | AA25: 7 | AB25: D | AC25: D+ | AD25: 27 | AE25: 21 | AF25: 0.8 | AG25: 0.88 | AH25: 0 | AI25: 0 | AJ25: =SUMIFS(AH$8:AH$1039,$O$8:$O$1039,O25,$AB$8:$AB$1039,AB25,$R$8:$R$1039,R25,$AA$8:$AA$1039,"<="&AA25) -> 0 | AK25: =E11 -> 35 | AL25: =E17 -> 0 | AM25: =MAX(0,AJ25-AK25) -> 0 | AN25: =IF(AM25=0,AH25,IF(AM25>=AH25,0,AH25-AM25)) -> 0 | AO25: =IF(AM25>=AH25,AI25,AI25*AM25/AH25) -> 0 | AP25: {=INDEX($AU$8:$BB$25,6*(R25-1)+MATCH(AB25,$AS$8:$AS$13,0),MATCH(O25,$AU$7:$BB$7,0))} -> TRUE | AR25: 3 | AS25: F | AT25: F+ | AU25: =AND(SUMIFS($AN$8:$AN$1039,$O$8:$O$1039,AU7,$AB$8:$AB$1039,AS25,$R$8:$R$1039,AR25)<=E13,SUMIFS($AO$8:$AO$1039,$O$8:$O$1039,AU7,$AB$8:$AB$1039,AS25,$R$8:$R$1039,AR25)<=E19) -> TRUE | AV25: =AND(SUMIFS($AN$8:$AN$1039,$O$8:$O$1039,AV7,$AB$8:$AB$1039,AS25,$R$8:$R$1039,AR25)<=E25,SUMIFS($AO$8:$AO$1039,$O$8:$O$1039,AV7,$AB$8:$AB$1039,AS25,$R$8:$R$1039,AR25)<=E31) -> TRUE | AW25: =AND(SUMIFS($AN$8:$AN$1039,$O$8:$O$1039,AW7,$AB$8:$AB$1039,AS25,$R$8:$R$1039,AR25)<=E37,SUMIFS($AO$8:$AO$1039,$O$8:$O$1039,AW7,$AB$8:$AB$1039,AS25,$R$8:$R$1039,AR25)<=E43) -> TRUE | AX25: =AND(SUMIFS($AN$8:$AN$1039,$O$8:$O$1039,AX7,$AB$8:$AB$1039,AS25,$R$8:$R$1039,AR25)<=E49,SUMIFS($AO$8:$AO$1039,$O$8:$O$1039,AX7,$AB$8:$AB$1039,AS25,$R$8:$R$1039,AR25)<=E55) -> TRUE | AY25: =AND(SUMIFS($AN$8:$AN$1039,$O$8:$O$1039,AY7,$AB$8:$AB$1039,AS25,$R$8:$R$1039,AR25)<=E61,SUMIFS($AO$8:$AO$1039,$O$8:$O$1039,AY7,$AB$8:$AB$1039,AS25,$R$8:$R$1039,AR25)<=E67) -> TRUE | AZ25: =AND(SUMIFS($AN$8:$AN$1039,$O$8:$O$1039,AZ7,$AB$8:$AB$1039,AS25,$R$8:$R$1039,AR25)<=E73,SUMIFS($AO$8:$AO$1039,$O$8:$O$1039,AZ7,$AB$8:$AB$1039,AS25,$R$8:$R$1039,AR25)<=E79) -> TRUE | BA25: =AND(SUMIFS($AN$8:$AN$1039,$O$8:$O$1039,BA7,$AB$8:$AB$1039,AS25,$R$8:$R$1039,AR25)<=E85,SUMIFS($AO$8:$AO$1039,$O$8:$O$1039,BA7,$AB$8:$AB$1039,AS25,$R$8:$R$1039,AR25)<=E91) -> TRUE | BB25: =AND(SUMIFS($AN$8:$AN$1039,$O$8:$O$1039,BB7,$AB$8:$AB$1039,AS25,$R$8:$R$1039,AR25)<=E97,SUMIFS($AO$8:$AO$1039,$O$8:$O$1039,BB7,$AB$8:$AB$1039,AS25,$R$8:$R$1039,AR25)<=E103) -> TRUE
B26: A+ | O26: Q1’26 | P26: 1 | Q26: 7 | R26: 1 | T26: =(S26+S27+S28)=N2 -> FALSE | X26: =MAX(S23-S26,0) -> 0 | Y26: 0 | AA26: 9 | AB26: D | AC26: D+ | AD26: 17 | AE26: 13 | AF26: 0.8 | AG26: 0.88 | AH26: 0 | AI26: 0 | AJ26: =SUMIFS(AH$8:AH$1039,$O$8:$O$1039,O26,$AB$8:$AB$1039,AB26,$R$8:$R$1039,R26,$AA$8:$AA$1039,"<="&AA26) -> 0 | AK26: =C11 -> 50 | AL26: =C17 -> 0 | AM26: =MAX(0,AJ26-AK26) -> 0 | AN26: =IF(AM26=0,AH26,IF(AM26>=AH26,0,AH26-AM26)) -> 0 | AO26: =IF(AM26>=AH26,AI26,AI26*AM26/AH26) -> 0 | AP26: {=INDEX($AU$8:$BB$25,6*(R26-1)+MATCH(AB26,$AS$8:$AS$13,0),MATCH(O26,$AU$7:$BB$7,0))} -> TRUE
B27: B+ | O27: Q1’26 | P27: 1 | Q27: 7 | R27: 2 | T27: =(S26+S27+S28)=N2 -> FALSE | X27: =MAX(S24-S27,0) -> 0 | Y27: 0 | AA27: 9 | AB27: D | AC27: D+ | AD27: 17 | AE27: 13 | AF27: 0.8 | AG27: 0.88 | AH27: 0 | AI27: 0 | AJ27: =SUMIFS(AH$8:AH$1039,$O$8:$O$1039,O27,$AB$8:$AB$1039,AB27,$R$8:$R$1039,R27,$AA$8:$AA$1039,"<="&AA27) -> 0 | AK27: =D11 -> 50 | AL27: =D17 -> 0 | AM27: =MAX(0,AJ27-AK27) -> 0 | AN27: =IF(AM27=0,AH27,IF(AM27>=AH27,0,AH27-AM27)) -> 0 | AO27: =IF(AM27>=AH27,AI27,AI27*AM27/AH27) -> 0 | AP27: {=INDEX($AU$8:$BB$25,6*(R27-1)+MATCH(AB27,$AS$8:$AS$13,0),MATCH(O27,$AU$7:$BB$7,0))} -> TRUE
B28: C+ | J28: =4/16 -> 0.25 | O28: Q1’26 | P28: 1 | Q28: 7 | R28: 3 | T28: =(S26+S27+S28)=N2 -> FALSE | X28: =MAX(S25-S28,0) -> 0 | Y28: 0 | AA28: 9 | AB28: D | AC28: D+ | AD28: 17 | AE28: 13 | AF28: 0.8 | AG28: 0.88 | AH28: 0 | AI28: 0 | AJ28: =SUMIFS(AH$8:AH$1039,$O$8:$O$1039,O28,$AB$8:$AB$1039,AB28,$R$8:$R$1039,R28,$AA$8:$AA$1039,"<="&AA28) -> 0 | AK28: =E11 -> 35 | AL28: =E17 -> 0 | AM28: =MAX(0,AJ28-AK28) -> 0 | AN28: =IF(AM28=0,AH28,IF(AM28>=AH28,0,AH28-AM28)) -> 0 | AO28: =IF(AM28>=AH28,AI28,AI28*AM28/AH28) -> 0 | AP28: {=INDEX($AU$8:$BB$25,6*(R28-1)+MATCH(AB28,$AS$8:$AS$13,0),MATCH(O28,$AU$7:$BB$7,0))} -> TRUE
B29: D+ | O29: Q1’26 | P29: 1 | Q29: 8 | R29: 1 | T29: =(S29+S30+S31)=N2 -> FALSE | X29: =MAX(S26-S29,0) -> 0 | Y29: 0 | AA29: 1 | AB29: A | AC29: A+ | AD29: 18 | AE29: 16 | AF29: 0.78 | AG29: 0.84 | AH29: 0 | AI29: 0 | AJ29: =SUMIFS(AH$8:AH$1039,$O$8:$O$1039,O29,$AB$8:$AB$1039,AB29,$R$8:$R$1039,R29,$AA$8:$AA$1039,"<="&AA29) -> 0 | AK29: =C8 -> 50 | AL29: =C14 -> 0 | AM29: =MAX(0,AJ29-AK29) -> 0 | AN29: =IF(AM29=0,AH29,IF(AM29>=AH29,0,AH29-AM29)) -> 0 | AO29: =IF(AM29>=AH29,AI29,AI29*AM29/AH29) -> 0 | AP29: {=INDEX($AU$8:$BB$25,6*(R29-1)+MATCH(AB29,$AS$8:$AS$13,0),MATCH(O29,$AU$7:$BB$7,0))} -> TRUE
B30: E+ | O30: Q1’26 | P30: 1 | Q30: 8 | R30: 2 | T30: =(S29+S30+S31)=N2 -> FALSE | X30: =MAX(S27-S30,0) -> 0 | Y30: 0 | AA30: 1 | AB30: A | AC30: A+ | AD30: 18 | AE30: 16 | AF30: 0.78 | AG30: 0.84 | AH30: 0 | AI30: 0 | AJ30: =SUMIFS(AH$8:AH$1039,$O$8:$O$1039,O30,$AB$8:$AB$1039,AB30,$R$8:$R$1039,R30,$AA$8:$AA$1039,"<="&AA30) -> 0 | AK30: =D8 -> 35 | AL30: =D14 -> 0 | AM30: =MAX(0,AJ30-AK30) -> 0 | AN30: =IF(AM30=0,AH30,IF(AM30>=AH30,0,AH30-AM30)) -> 0 | AO30: =IF(AM30>=AH30,AI30,AI30*AM30/AH30) -> 0 | AP30: {=INDEX($AU$8:$BB$25,6*(R30-1)+MATCH(AB30,$AS$8:$AS$13,0),MATCH(O30,$AU$7:$BB$7,0))} -> TRUE
B31: F+ | F31: Fab 1 space | G31: Fab 2 space | H31: Fab 3 space | O31: Q1’26 | P31: 1 | Q31: 8 | R31: 3 | T31: =(S29+S30+S31)=N2 -> FALSE | X31: =MAX(S28-S31,0) -> 0 | Y31: 0 | AA31: 1 | AB31: A | AC31: A+ | AD31: 18 | AE31: 16 | AF31: 0.78 | AG31: 0.84 | AH31: 0 | AI31: 0 | AJ31: =SUMIFS(AH$8:AH$1039,$O$8:$O$1039,O31,$AB$8:$AB$1039,AB31,$R$8:$R$1039,R31,$AA$8:$AA$1039,"<="&AA31) -> 0 | AK31: =E8 -> 0 | AL31: =E14 -> 0 | AM31: =MAX(0,AJ31-AK31) -> 0 | AN31: =IF(AM31=0,AH31,IF(AM31>=AH31,0,AH31-AM31)) -> 0 | AO31: =IF(AM31>=AH31,AI31,AI31*AM31/AH31) -> 0 | AP31: {=INDEX($AU$8:$BB$25,6*(R31-1)+MATCH(AB31,$AS$8:$AS$13,0),MATCH(O31,$AU$7:$BB$7,0))} -> TRUE
A32: WS Component for Q3’26 | B32: A | F32: {=SUM(C32:C43*data!$B$3:$B$14)} -> 0 | G32: {=SUM(D32:D43*data!$B$3:$B$14)} -> 0 | H32: {=SUM(E32:E43*data!$B$3:$B$14)} -> 0 | I32: <- make sure its green | O32: Q1’26 | P32: 1 | Q32: 9 | R32: 1 | T32: =(S32+S33+S34)=N2 -> FALSE | X32: =MAX(S29-S32,0) -> 0 | Y32: 0 | AA32: 2 | AB32: A | AC32: A+ | AD32: 16 | AE32: 13 | AF32: 0.78 | AG32: 0.84 | AH32: 0 | AI32: 0 | AJ32: =SUMIFS(AH$8:AH$1039,$O$8:$O$1039,O32,$AB$8:$AB$1039,AB32,$R$8:$R$1039,R32,$AA$8:$AA$1039,"<="&AA32) -> 0 | AK32: =C8 -> 50 | AL32: =C14 -> 0 | AM32: =MAX(0,AJ32-AK32) -> 0 | AN32: =IF(AM32=0,AH32,IF(AM32>=AH32,0,AH32-AM32)) -> 0 | AO32: =IF(AM32>=AH32,AI32,AI32*AM32/AH32) -> 0 | AP32: {=INDEX($AU$8:$BB$25,6*(R32-1)+MATCH(AB32,$AS$8:$AS$13,0),MATCH(O32,$AU$7:$BB$7,0))} -> TRUE
B33: B | O33: Q1’26 | P33: 1 | Q33: 9 | R33: 2 | T33: =(S32+S33+S34)=N2 -> FALSE | X33: =MAX(S30-S33,0) -> 0 | Y33: 0 | AA33: 2 | AB33: A | AC33: A+ | AD33: 16 | AE33: 13 | AF33: 0.78 | AG33: 0.84 | AH33: 0 | AI33: 0 | AJ33: =SUMIFS(AH$8:AH$1039,$O$8:$O$1039,O33,$AB$8:$AB$1039,AB33,$R$8:$R$1039,R33,$AA$8:$AA$1039,"<="&AA33) -> 0 | AK33: =D8 -> 35 | AL33: =D14 -> 0 | AM33: =MAX(0,AJ33-AK33) -> 0 | AN33: =IF(AM33=0,AH33,IF(AM33>=AH33,0,AH33-AM33)) -> 0 | AO33: =IF(AM33>=AH33,AI33,AI33*AM33/AH33) -> 0 | AP33: {=INDEX($AU$8:$BB$25,6*(R33-1)+MATCH(AB33,$AS$8:$AS$13,0),MATCH(O33,$AU$7:$BB$7,0))} -> TRUE
B34: C | F34: New tool purchase cost | O34: Q1’26 | P34: 1 | Q34: 9 | R34: 3 | T34: =(S32+S33+S34)=N2 -> FALSE | X34: =MAX(S31-S34,0) -> 0 | Y34: 0 | AA34: 2 | AB34: A | AC34: A+ | AD34: 16 | AE34: 13 | AF34: 0.78 | AG34: 0.84 | AH34: 0 | AI34: 0 | AJ34: =SUMIFS(AH$8:AH$1039,$O$8:$O$1039,O34,$AB$8:$AB$1039,AB34,$R$8:$R$1039,R34,$AA$8:$AA$1039,"<="&AA34) -> 0 | AK34: =E8 -> 0 | AL34: =E14 -> 0 | AM34: =MAX(0,AJ34-AK34) -> 0 | AN34: =IF(AM34=0,AH34,IF(AM34>=AH34,0,AH34-AM34)) -> 0 | AO34: =IF(AM34>=AH34,AI34,AI34*AM34/AH34) -> 0 | AP34: {=INDEX($AU$8:$BB$25,6*(R34-1)+MATCH(AB34,$AS$8:$AS$13,0),MATCH(O34,$AU$7:$BB$7,0))} -> TRUE
B35: D | F35: {=SUM( _xlfn.BYROW( IF(C32:E43-C20:E31>0, C32:E43-C20:E31, 0), _xleta.SUM) *data!$C$3:$C$14 )} -> 0 | O35: Q1’26 | P35: 1 | Q35: 10 | R35: 1 | T35: =(S35+S36+S37)=N2 -> FALSE | X35: =MAX(S32-S35,0) -> 0 | Y35: 0 | AA35: 6 | AB35: D | AC35: D+ | AD35: 14 | AE35: 11 | AF35: 0.8 | AG35: 0.88 | AH35: 0 | AI35: 0 | AJ35: =SUMIFS(AH$8:AH$1039,$O$8:$O$1039,O35,$AB$8:$AB$1039,AB35,$R$8:$R$1039,R35,$AA$8:$AA$1039,"<="&AA35) -> 0 | AK35: =C11 -> 50 | AL35: =C17 -> 0 | AM35: =MAX(0,AJ35-AK35) -> 0 | AN35: =IF(AM35=0,AH35,IF(AM35>=AH35,0,AH35-AM35)) -> 0 | AO35: =IF(AM35>=AH35,AI35,AI35*AM35/AH35) -> 0 | AP35: {=INDEX($AU$8:$BB$25,6*(R35-1)+MATCH(AB35,$AS$8:$AS$13,0),MATCH(O35,$AU$7:$BB$7,0))} -> TRUE
B36: E | F36: Moveout cost | O36: Q1’26 | P36: 1 | Q36: 10 | R36: 2 | T36: =(S35+S36+S37)=N2 -> FALSE | X36: =MAX(S33-S36,0) -> 0 | Y36: 0 | AA36: 6 | AB36: D | AC36: D+ | AD36: 14 | AE36: 11 | AF36: 0.8 | AG36: 0.88 | AH36: 0 | AI36: 0 | AJ36: =SUMIFS(AH$8:AH$1039,$O$8:$O$1039,O36,$AB$8:$AB$1039,AB36,$R$8:$R$1039,R36,$AA$8:$AA$1039,"<="&AA36) -> 0 | AK36: =D11 -> 50 | AL36: =D17 -> 0 | AM36: =MAX(0,AJ36-AK36) -> 0 | AN36: =IF(AM36=0,AH36,IF(AM36>=AH36,0,AH36-AM36)) -> 0 | AO36: =IF(AM36>=AH36,AI36,AI36*AM36/AH36) -> 0 | AP36: {=INDEX($AU$8:$BB$25,6*(R36-1)+MATCH(AB36,$AS$8:$AS$13,0),MATCH(O36,$AU$7:$BB$7,0))} -> TRUE
B37: F | F37: {=SUM( _xlfn.BYROW( IF(C32:E43-C20:E31<0, C32:E43-C20:E31, 0), _xleta.SUM) * -1000000 )} -> 0 | O37: Q1’26 | P37: 1 | Q37: 10 | R37: 3 | T37: =(S35+S36+S37)=N2 -> FALSE | X37: =MAX(S34-S37,0) -> 0 | Y37: 0 | AA37: 6 | AB37: D | AC37: D+ | AD37: 14 | AE37: 11 | AF37: 0.8 | AG37: 0.88 | AH37: 0 | AI37: 0 | AJ37: =SUMIFS(AH$8:AH$1039,$O$8:$O$1039,O37,$AB$8:$AB$1039,AB37,$R$8:$R$1039,R37,$AA$8:$AA$1039,"<="&AA37) -> 0 | AK37: =E11 -> 35 | AL37: =E17 -> 0 | AM37: =MAX(0,AJ37-AK37) -> 0 | AN37: =IF(AM37=0,AH37,IF(AM37>=AH37,0,AH37-AM37)) -> 0 | AO37: =IF(AM37>=AH37,AI37,AI37*AM37/AH37) -> 0 | AP37: {=INDEX($AU$8:$BB$25,6*(R37-1)+MATCH(AB37,$AS$8:$AS$13,0),MATCH(O37,$AU$7:$BB$7,0))} -> TRUE
B38: A+ | O38: Q1’26 | P38: 1 | Q38: 11 | R38: 1 | T38: =(S38+S39+S40)=N2 -> FALSE | X38: =MAX(S35-S38,0) -> 0 | Y38: 0 | AA38: 3 | AB38: F | AC38: F+ | AD38: 18 | AE38: 16 | AF38: 0.8 | AG38: 0.9 | AH38: 0 | AI38: 0 | AJ38: =SUMIFS(AH$8:AH$1039,$O$8:$O$1039,O38,$AB$8:$AB$1039,AB38,$R$8:$R$1039,R38,$AA$8:$AA$1039,"<="&AA38) -> 0 | AK38: =C13 -> 90 | AL38: =C19 -> 0 | AM38: =MAX(0,AJ38-AK38) -> 0 | AN38: =IF(AM38=0,AH38,IF(AM38>=AH38,0,AH38-AM38)) -> 0 | AO38: =IF(AM38>=AH38,AI38,AI38*AM38/AH38) -> 0 | AP38: {=INDEX($AU$8:$BB$25,6*(R38-1)+MATCH(AB38,$AS$8:$AS$13,0),MATCH(O38,$AU$7:$BB$7,0))} -> TRUE
B39: B+ | O39: Q1’26 | P39: 1 | Q39: 11 | R39: 2 | T39: =(S38+S39+S40)=N2 -> FALSE | X39: =MAX(S36-S39,0) -> 0 | Y39: 0 | AA39: 3 | AB39: F | AC39: F+ | AD39: 18 | AE39: 16 | AF39: 0.8 | AG39: 0.9 | AH39: 0 | AI39: 0 | AJ39: =SUMIFS(AH$8:AH$1039,$O$8:$O$1039,O39,$AB$8:$AB$1039,AB39,$R$8:$R$1039,R39,$AA$8:$AA$1039,"<="&AA39) -> 0 | AK39: =D13 -> 60 | AL39: =D19 -> 0 | AM39: =MAX(0,AJ39-AK39) -> 0 | AN39: =IF(AM39=0,AH39,IF(AM39>=AH39,0,AH39-AM39)) -> 0 | AO39: =IF(AM39>=AH39,AI39,AI39*AM39/AH39) -> 0 | AP39: {=INDEX($AU$8:$BB$25,6*(R39-1)+MATCH(AB39,$AS$8:$AS$13,0),MATCH(O39,$AU$7:$BB$7,0))} -> TRUE
B40: C+ | O40: Q1’26 | P40: 1 | Q40: 11 | R40: 3 | T40: =(S38+S39+S40)=N2 -> FALSE | X40: =MAX(S37-S40,0) -> 0 | Y40: 0 | AA40: 3 | AB40: F | AC40: F+ | AD40: 18 | AE40: 16 | AF40: 0.8 | AG40: 0.9 | AH40: 0 | AI40: 0 | AJ40: =SUMIFS(AH$8:AH$1039,$O$8:$O$1039,O40,$AB$8:$AB$1039,AB40,$R$8:$R$1039,R40,$AA$8:$AA$1039,"<="&AA40) -> 0 | AK40: =E13 -> 36 | AL40: =E19 -> 0 | AM40: =MAX(0,AJ40-AK40) -> 0 | AN40: =IF(AM40=0,AH40,IF(AM40>=AH40,0,AH40-AM40)) -> 0 | AO40: =IF(AM40>=AH40,AI40,AI40*AM40/AH40) -> 0 | AP40: {=INDEX($AU$8:$BB$25,6*(R40-1)+MATCH(AB40,$AS$8:$AS$13,0),MATCH(O40,$AU$7:$BB$7,0))} -> TRUE
...

Sheet data
A1: Space data | I1: Step Matrix
A2: WS | B2: sqm | C2: cost | G2: Mintech preference rank | H2: N-S | I2: Node | J2: Step Name | K2: WS | L2: RPT (min) | M2: WS(TOR) | N2: RPT(TOR) | O2: Ratio
A3: A | B3: 6.78 | C3: 4500000 | D3: 0.78 | G3: 1 | H3: =I3&J3 -> 18 | I3: 1 | J3: 8 | K3: A | L3: 18 | M3: A+ | N3: 16 | O3: =L3/N3 -> 1.125
A4: B | B4: 3.96 | C4: 6000000 | D4: 0.76 | G4: 2 | H4: =I4&J4 -> 19 | I4: 1 | J4: 9 | K4: A | L4: 16 | M4: A+ | N4: 13 | O4: =L4/N4 -> 1.2307692
A5: C | B5: 5.82 | C5: 2200000 | D5: 0.8 | G5: 3 | H5: =I5&J5 -> 14 | I5: 1 | J5: 4 | K5: A | L5: 20 | M5: A+ | N5: 16 | O5: =L5/N5 -> 1.25
A6: D | B6: 5.61 | C6: 4000000 | D6: 0.8 | G6: 1 | H6: =I6&J6 -> 22 | I6: 2 | J6: 2 | K6: B | L6: 20 | M6: B+ | N6: 18 | O6: =L6/N6 -> 1.1111111
A7: E | B7: 4.65 | C7: 3500000 | D7: 0.76 | G7: 2 | H7: =I7&J7 -> 24 | I7: 2 | J7: 4 | K7: B | L7: 25 | M7: B+ | N7: 19 | O7: =L7/N7 -> 1.3157895
A8: F | B8: 3.68 | C8: 6000000 | D8: 0.8 | G8: 3 | H8: =I8&J8 -> 25 | I8: 2 | J8: 5 | K8: B | L8: 15 | M8: B+ | N8: 11 | O8: =L8/N8 -> 1.3636364
A9: A+ | B9: 6.93 | C9: 6000000 | D9: 0.84 | G9: 4 | H9: =I9&J9 -> 28 | I9: 2 | J9: 8 | K9: B | L9: 22 | M9: B+ | N9: 16 | O9: =L9/N9 -> 1.375
A10: B+ | B10: 3.72 | C10: 8000000 | D10: 0.81 | G10: 1 | H10: =I10&J10 -> 31 | I10: 3 | J10: 1 | K10: C | L10: 21 | M10: C+ | N10: 20 | O10: =L10/N10 -> 1.05
A11: C+ | B11: 5.75 | C11: 3200000 | D11: 0.86 | G11: 2 | H11: =I11&J11 -> 314 | I11: 3 | J11: 14 | K11: C | L11: 12 | M11: C+ | N11: 11 | O11: =L11/N11 -> 1.0909091
A12: D+ | B12: 5.74 | C12: 5500000 | D12: 0.88 | G12: 3 | H12: =I12&J12 -> 37 | I12: 3 | J12: 7 | K12: C | L12: 24 | M12: C+ | N12: 21 | O12: =L12/N12 -> 1.1428571
A13: E+ | B13: 4.8 | C13: 5800000 | D13: 0.84 | G13: 4 | H13: =I13&J13 -> 316 | I13: 3 | J13: 16 | K13: C | L13: 25 | M13: C+ | N13: 20 | O13: =L13/N13 -> 1.25
A14: F+ | B14: 3.57 | C14: 8000000 | D14: 0.9 | G14: 5 | H14: =I14&J14 -> 38 | I14: 3 | J14: 8 | K14: C | L14: 19 | M14: C+ | N14: 13 | O14: =L14/N14 -> 1.4615385
C15: =SUM(C2:C14)*3 -> 188100000 | G15: 1 | H15: =I15&J15 -> 36 | I15: 3 | J15: 6 | K15: D | L15: 12 | M15: D+ | N15: 11 | O15: =L15/N15 -> 1.0909091
G16: 2 | H16: =I16&J16 -> 315 | I16: 3 | J16: 15 | K16: D | L16: 11 | M16: D+ | N16: 10 | O16: =L16/N16 -> 1.1
G17: 3 | H17: =I17&J17 -> 39 | I17: 3 | J17: 9 | K17: D | L17: 15 | M17: D+ | N17: 13 | O17: =L17/N17 -> 1.1538462
G18: 4 | H18: =I18&J18 -> 11 | I18: 1 | J18: 1 | K18: D | L18: 14 | M18: D+ | N18: 12 | O18: =L18/N18 -> 1.1666667
G19: 5 | H19: =I19&J19 -> 310 | I19: 3 | J19: 10 | K19: D | L19: 24 | M19: D+ | N19: 20 | O19: =L19/N19 -> 1.2
G20: 6 | H20: =I20&J20 -> 110 | I20: 1 | J20: 10 | K20: D | L20: 14 | M20: D+ | N20: 11 | O20: =L20/N20 -> 1.2727273
G21: 7 | H21: =I21&J21 -> 16 | I21: 1 | J21: 6 | K21: D | L21: 27 | M21: D+ | N21: 21 | O21: =L21/N21 -> 1.2857143
G22: 8 | H22: =I22&J22 -> 32 | I22: 3 | J22: 2 | K22: D | L22: 9 | M22: D+ | N22: 7 | O22: =L22/N22 -> 1.2857143
G23: 9 | H23: =I23&J23 -> 17 | I23: 1 | J23: 7 | K23: D | L23: 17 | M23: D+ | N23: 13 | O23: =L23/N23 -> 1.3076923
G24: 1 | H24: =I24&J24 -> 33 | I24: 3 | J24: 3 | K24: E | L24: 24 | M24: E+ | N24: 23 | O24: =L24/N24 -> 1.0434783
G25: 2 | H25: =I25&J25 -> 211 | I25: 2 | J25: 11 | K25: E | L25: 20 | M25: E+ | N25: 19 | O25: =L25/N25 -> 1.0526316
G26: 3 | H26: =I26&J26 -> 311 | I26: 3 | J26: 11 | K26: E | L26: 17 | M26: E+ | N26: 15 | O26: =L26/N26 -> 1.1333333
G27: 4 | H27: =I27&J27 -> 29 | I27: 2 | J27: 9 | K27: E | L27: 7 | M27: E+ | N27: 6 | O27: =L27/N27 -> 1.1666667
... G45: 11 | H45: =I45&J45 -> 15 | I45: 1 | J45: 5 | K45: F | L45: 12 | M45: F+ | N45: 9 | O45: =L45/N45 -> 1.3333333

Sheet Q1b
A1: Do not modify anything in this sheet except for the answer area | F1: Space available | M1: Quarter | N1: Q1’26 | O1: Q2’26 | P1: Q3’26 | Q1: Q4’26 | R1: Q1’27 | S1: Q2’27 | T1: Q3’27 | U1: Q4’27
F2: Fab 1 | G2: Fab 2 | H2: Fab 3 | K2: Total costs over 8 quarters | M2: Node 1 | N2: 12000 | O2: 10000 | P2: 8500 | Q2: 7500 | R2: 6000 | S2: 5000 | T2: 4000 | U2: 2000 | AP2: All capacity ok?
F3: 1500 | G3: 1300 | H3: 700 | J3: minimize this -> | K3: =F23+F35+F47+F59+F71+F83+F95+F25+F37+F49+F61+F73+F85+F97+Y6 -> 587000000 | M3: Node 2 | N3: 5000 | O3: 5200 | P3: 5400 | Q3: 5600 | R3: 6000 | S3: 6500 | T3: 7000 | U3: 7500 | AP3: =AND(AU8:BB25) -> TRUE | AQ3: <- make sure its green
A4: All constraints fulfilled? | B4: =AND(K7,V8,AP3) -> FALSE | C4: <- make sure its green | M4: Node 3 | N4: 3000 | O4: 4500 | P4: 7000 | Q4: 8000 | R4: 9000 | S4: 11000 | T4: 13000 | U4: 16000
O5: =ROUNDUP(45*O2/10080/0.84,0) -> 54 | P5: =ROUNDUP(45*P2/10080/0.84,0) -> 46 | Q5: =ROUNDUP(45*Q2/10080/0.84,0) -> 40 | R5: =ROUNDUP(45*R2/10080/0.84,0) -> 32 | S5: =ROUNDUP(45*S2/10080/0.84,0) -> 27 | T5: =ROUNDUP(45*T2/10080/0.84,0) -> 22 | AU5: Enough mintech + TOR tools to run the assigned loading?
C6: Tooling plan (to fill) | F6: Solution Validation | K6: All space within limit? | O6: Node Wafer Stepflow Distribution for each fab for each quarter | T6: Solution Validation | V6: All loading fulfilled? | X6: Total transfer costs: | Y6: =SUM(_xlfn.ANCHORARRAY(Y8)) -> 0 | AB6: mintech | AC6: TOR | AD6: mintech | AE6: TOR | AF6: mintech | AG6: TOR | AH6: mintech | AI6: TOR | AJ6: mintech | AK6: mintech | AL6: TOR | AM6: mintech | AN6: mintech | AO6: TOR | AP6: Enough mintech + TOR tools to run the assigned loading?
B7: WS Name | C7: Fab 1 - WS Count | D7: Fab 2 - WS Count | E7: Fab 3 - WS Count | F7: Fab 1 space | G7: Fab 2 space | H7: Fab 3 space | K7: {=AND(F8:H8<$F$3:$H$3,F20:H20<$F$3:$H$3,F32:H32<$F$3:$H$3,F44:H44<$F$3:$H$3,F56:H56<$F$3:$H$3,F68:H68<$F$3:$H$3,F80:H80<$F$3:$H$3,F92:H92<$F$3:$H$3)} -> TRUE | O7: Quarter | P7: Node | Q7: Step | R7: Fab | S7: Loading (to fill) | T7: Loading fulfilled? | X7: Cross-fab transfer count | Y7: Transfer costs | AA7: Mintech preference rank | AB7: WS (mintech) | AC7: WS (TOR) | AD7: RPT (mintech) | AE7: RPT (TOR) | AF7: Util (mintech) | AG7: Util (TOR) | AH7: Tool requirement if running on mintech | AI7: Tool requirement if running on TOR | AJ7: Cumulative mintech req | AK7: Available mintech tools | AL7: Available TOR tools | AM7: Overflow cumreq | AN7: Req on mintech | AO7: Req on TOR | AR7: Fab | AU7: Q1’26 | AV7: Q2’26 | AW7: Q3’26 | AX7: Q4’26 | AY7: Q1’27 | AZ7: Q2’27 | BA7: Q3’27 | BB7: Q4’27
